Workbook

Sheet raw
A1: Item No. | B1: Section | C1: Issue | D1: MoSCoW | E1: Issue Type (None/Bug/Rework/Enhancement) by HAESL | F1: Comments | G1: Issue Raise Date | H1: Raised by | I1: Screen Capture | J1: Issue Type (None/Bug/Rework/Enhancement) by RR | K1: Priority Classification (by RR) | L1: User Story No (by RR) | M1: Comments (by RR) | N1: Change Request Accepted by HAESL(For Enhancements Only) | O1: HAESL Comments | P1: Comment date, Commented by | Q1: Closed/Fixed/Not yet fix
A2: 1 | B2: Admin - Task Owner Setting | C2: System | D2: Must | E2: Bug | F2: Duplicate User show in the list when click "MR" | G2: 46097 | H2: Ray | I2: Refer to Screen Capture | J2: Bug | K2: P4 | M2: Suspecting this can be observed when two users performing same operation at atime. Not able to reproduce it in dev by single user | O2: Low, no issue now | Q2: Fixed
A3: 2 | B3: Admin - Template Management | C3: UI | D3: Must | E3: Bug | F3: Please remove "Hospital", "Check & Repair", "1st Refurbishment", "2nd Refurbishment", "Mature Refurbishment" from the dropdown list. | G3: 46097 | H3: Ray | I3: Refer to Screen Capture | J3: Bug | K3: P4 | M3: Entries to be removed | O3: Low, no issue now | Q3: Fixed
F4: Add "OH" in the list
A5: 3 | B5: Admin - Gate Setting | C5: System | D5: Must | E5: Bug | F5: Unable to show gate "1A" after create. | G5: 46097 | H5: Ray | I5: Refer to Screen Capture | J5: Bug | K5: P4 | M5: Suspecting this can be observed when two users performing same operation at atime. Not able to reproduce it in dev by single user | O5: Low, no issue now | Q5: Fixed
A6: 4 | B6: Notification | C6: System | D6: Must | E6: Bug | F6: Unable to clear notifcations from notifcation list. After clicking the "X", the same notifcation will pop up again later, all the notifications become accumulate as a huge list. | G6: 46097 | H6: Ray | I6: Refer to Screen Capture | J6: None | M6: Not able to reproduce in dev | O6: Low, but the counter of msg delayed | Q6: Fixed
A7: 5 | B7: Planner - Create Streamer | C7: System | D7: Must | E7: Bug | F7: Induction date cannot be backdated. | G7: 46097 | H7: Ricky | I7: Refer to Screen Capture | J7: Bug | K7: P2 | M7: Fixed | O7: Medium, not fixed | Q7: Unstable Fix
A8: 6 | B8: Planner - Create Streamer | C8: System | D8: Must | E8: Bug | F8: Dispatch Module S/N cannot be updated. | G8: 46097 | H8: Ricky | I8: Refer to Screen Capture | J8: None | M8: As per requirement | O8: Medium | Q8: Fixed
A9: 7 | B9: Planner - Task | C9: UI | D9: Should | E9: Bug | F9: The table cells borders is not align | G9: 46098 | H9: Ray | I9: Refer to Screen Capture | J9: Bug | K9: P4 | M9: Working with Syncfusion on it | O9: Low, not yet fixed | Q9: Not yet fix
A10: 8 | B10: Planner - Task | C10: System | D10: Must | E10: Bug | F10: Showing unexpected date range after filter | G10: 46098 | H10: Ray | I10: Refer to Screen Capture | J10: None | O10: High, function disappeared | Q10: Not yet fix
A11: 9 | B11: Planner - Task | C11: System | D11: Must | E11: Rework | F11: Missing implement of Post UAT item U08 | G11: 46098 | H11: Ray | I11: Refer to Screen Capture | J11: None | O11: Removed | Q11: Closed
A12: 10 | B12: Planner - Create Streamer / Edit Streamer | C12: System | D12: Must | E12: None | F12: Inconsistency of value "Retain", if the row added by user, system shows "Retain", if the row is recongnise by PDF, system show "RETAIN". Please update all to capital letter. | G12: 46098 | H12: Ray | I12: Refer to Screen Capture | J12: Bug | K12: P4 | M12: Fixed | O12: Low | Q12: Fixed
A13: 11 | B13: Engine Type List | C13: UI | D13: Should | E13: None | F13: Sort the engine type list in alphabetical sequence | G13: 46098 | H13: Ray | I13: Refer to Screen Capture | J13: Enhancement | M13: Not a bug, to be addressed as new request | O13: Low, fixed | Q13: Fixed
A14: 12 | B14: Admin - Template Create - Task Selection | C14: System | D14: Must | E14: None | F14: For Module Level tasks (Items 5, 9, 15, 32, 33, and 39), updating the top‑level item should also update the sub‑tasks automatically. | G14: 46098 | H14: Edmond | I14: Refer to Screen Capture | J14: None | M14: No action | O14: High, operational risk | Q14: Fixed
A15: 13 | B15: Planner - Tasks | C15: System | D15: Must | E15: Bug | F15: Update Task 4 Finish Date: | G15: 46097 | H15: Ricky | I15: Refer to Screen Capture | J15: None | M15: Dev to reproduce issue | O15: Low, fixed | Q15: Fixed
F16: 1. 41500 was created on 17 Mar 2026, and Task 4 actual completion date is 17 Mar 2026; however, it is currently showing as 16 Mar 2026.
F17: 2. Unable to select “Cancel for Approval.”
A18: 14 | B18: Planner - Tasks | C18: System | D18: Must | E18: Bug | F18: Update Task 4 Finish Date: | G18: 46097 | H18: Ricky | I18: Refer to Screen Capture | J18: None | M18: Dev to reproduce issue | O18: high, operational risk | Q18: Not yet fix
F19: Job 21231 was completed on 17 May 2026. The completion date was entered as 16 Mar 2026; however, it is not reflected under “Actual Completion.”
F20: 2. Unable to select “Cancel for Approval.”
A21: 15 | B21: Notification - Line Manager | C21: System | D21: Must | E21: Bug | F21: No items in the line manager notification list even there are few items are pending approval | G21: 46098 | H21: Ray | I21: Refer to Screen Capture | J21: Bug | K21: P3 | M21: Notifications seems to disappear in View All screen | O21: high, bug | Q21: Not yet fix
A22: 16 | B22: Input Type | C22: UI | D22: Should | E22: None | F22: Please update the default value to "Engine", currently is "Others". HAESL major business is "Engine". | G22: 46098 | H22: Ray | I22: N/A | J22: Enhancement | M22: Changes to be done | O22: Low, fixed | Q22: Fixed
A23: 17 | B23: System | C23: System | D23: Must | E23: Bug | F23: Unstable of system access, frequently time out/no response when access the system main page, active streamer page | G23: 46098 | H23: Ray | I23: Refer to Screen Capture | J23: Bug | K23: P4 | M23: Need more details from HAESL on timeout duration and to be verified against NFR | O23: high, operational risk | Q23: Not yet fix
A24: 18 | B24: System | C24: System | D24: Should | E24: None | F24: Please remove the "Overview" button if nothing was developed under this page | G24: 46098 | H24: Ray | I24: Refer to Screen Capture | J24: Enhancement | M24: To be removed | O24: Low, fixed | Q24: Fixed
A25: 19 | B25: Admin - Template Management | C25: System | D25: Must | E25: Bug | F25: When two users edit the same template and press save, system will create two templates with the same name. If we delete either one of them, both of the template will be deleted. Could the system lock the template if it is being edit to solve this problem? | G25: 46098 | H25: Edmond | I25: Refer to Screen Capture | J25: Bug | K25: P4 | M25: Needs to be addressed | O25: high, bug | Q25: Not yet fix
F26: Co-edit issue
A27: 20 | B27: Notification | C27: System | D27: Must | E27: Bug | F27: The hour counting is incorrect | G27: 46098 | H27: Ray | I27: Refer to Screen Capture | J27: Bug | K27: P4 | M27: Needs to be addressed | O27: Low | Q27: Fixed
A28: 21 | B28: Planner - Create Streamer | C28: System | D28: Must | E28: Bug | F28: When create streamer, module level task was unexpected disabled. | G28: 46098 | H28: Ray | I28: Refer to Screen Capture | J28: Bug | K28: P4 | M28: Need additional information | O28: Closed | Q28: Closed
A29: 22 | B29: Admin - Gate Setting, Module Setting & Task Setting | C29: System | D29: Must | E29: Bug | F29: The gate setting or module setting change, the template won't have any update. e.g. I delete the Gate 1B, but the Gate 1B still in the template. All the setting should be synchronize. | G29: 46098 | H29: Ray | I29: Refer to Screen Capture | J29: None | M29: As per requirement | O29: High | Q29: Fixed
A30: 23 | B30: Tasks | C30: System | D30: Must | E30: Bug | F30: Unexpected error after input ACD for the task and press save. | G30: 46098 | H30: Ray | I30: Refer to Screen Capture | J30: Bug | K30: P4 | M30: Unable to produce bug, Additional information needed | O30: high, fixed | Q30: Fixed
A31: 24 | B31: Notification - Line Manager | C31: System | D31: Must | E31: Bug | F31: When I click Accept on an approval task, the approvals list does not refresh immediately to remove the task card. I have to close and reopen the list to see the update. In addition, the task continues to display “Pending for approval”. | G31: 46098 | H31: Ray | I31: Refer to Screen Capture | J31: Bug | K31: P3 | M31: Needs to be addressed | O31: medium, operational risk | Q31: Fixed
A32: 25 | B32: Tasks | C32: System | D32: Must | E32: Bug | F32: Unable to cancel for approval when click "Cancel for Approval" button | G32: 46098 | H32: Ray | I32: Refer to Screen Capture | J32: None | O32: High | Q32: Not yet fix
A33: 26 | B33: Tasks | C33: System | D33: Must | E33: Bug | F33: After enter a late PCD, the reason for delay list is nothing inside | G33: 46098 | H33: Ray | I33: Refer to Screen Capture | J33: Bug | K33: P3 | M33: Fixed | O33: High, bug | Q33: Fixed
A34: 27 | B34: Tasks - Task Owner Filter | C34: System | D34: Must | E34: Bug | F34: The Task Owner drop-down list is not syncing with the latest Task Owner settings in Admin. Please update the list items and sort them in alphabetical order. | G34: 46099 | H34: Ray | I34: Refer to Screen Capture | J34: Bug | K34: P4 | M34: Needs to be synced | O34: Medium, bug | Q34: Fixed
A35: 28 | B35: Streamer - Module Level Task | C35: System | D35: Should | E35: None | F35: The sequence of module level task should follow the module sequence in admin setting | G35: 46099 | H35: Ray | I35: Refer to Screen Capture | J35: Enhancement | M35: To be changed as mentioned | O35: Medium, performance issues | Q35: Fixed
A36: 29 | B36: Tasks - Task Owner Filter | C36: System | D36: Must | E36: Bug | F36: Duplicate selection items found. | G36: 46099 | H36: Ray | I36: Refer to Screen Capture | J36: Bug | K36: P4 | M36: Needs to be addressed | O36: medium, fixed | Q36: Fixed
A37: 30 | B37: Tasks | C37: System | D37: Must | E37: Bug | F37: Planner / Task Owner should not able to disable a task when the task already completed. (L02) | G37: 46099 | H37: Ray | I37: Refer to Screen Capture | J37: None | M37: Changes as per L02 | O37: medium, fixed | Q37: Fixed
A38: 31 | B38: Tasks - Approval Process | C38: System | D38: Must | E38: Bug | F38: The list of pending approval tasks do not align with the actual pending approval task | G38: 46099 | H38: Ray | I38: Refer to Screen Capture | J38: Bug | K38: P4 | M38: Needs to be addressed | O38: High, bug | Q38: Fixed
B39: Notification - Approval
A40: 32 | B40: Admin - Task Selection update | C40: System | D40: Must | E40: Bug | F40: When user update column Start Day and Duration value, system will auto selected the row, it is not what we expect. | G40: 46099 | H40: Ricky | I40: Refer to Screen Capture | J40: Bug | K40: P4 | M40: As per email with Ray, auto selection to be removed | O40: medium, operational risk | Q40: Fixed
...

Sheet classifications
A1: Category | B1: Desciption | C1: Appearance
A2: Swap Module | B2: it is related to the off-module list to interact with the active streamer. In practice terms, the module can be selected from the off-module list to swap into the existing engine streamer on the Streamer Section as a planner role. | C2: =COUNTIF(wiki!R:R,classifications!A2) -> 7
A3: Task Owner View | B3: it is all about tasks allocated from the streamer and give the task owner to control their own tasks on the calendar view on task section. They can change the projected completion date (PCD), input actual completion date (ACD) with delayed reasons if any as well as request and approve the request if any trigger is needed. | C3: =COUNTIF(wiki!R:R,classifications!A3) -> 5
A4: Notification | B4: On Notification, there are two area for notifying the task owners. Firstly, it is general message notfiication from the task actions like changing the task date from different planner or task owners. Another notification type is to notify the line manager as a supper task owner to accept or reject the approval requests from the staff under the same department group. | C4: =COUNTIF(wiki!R:R,classifications!A4) -> 25
A5: DIW/Cost Review | B5: In specific streamer arrangement, the template with the label of DIW/Cost Review can be selected. Once the status of the active streamer is under the status of DIW/Cost Review, the planner would release the investigation or quotation after all tasks are completed in the first induction. Therefore, the planner is able to re-input the second induction information later on. | C5: =COUNTIF(wiki!R:R,classifications!A5) -> 4

Sheet calc
A1: Category | B1: Critical Priority | C1: Appearance
A2: Swap Module | B2: Low | C2: 2
B3: Medium | C3: 2
B4: High | C4: 2
A5: Task Owner View | B5: Low | C5: 1
B6: Medium | C6: 3
B7: High | C7: 1
A8: Notification | B8: Low | C8: 5
B9: Medium | C9: 11
B10: High | C10: 9
A11: DIW/Cost Review | B11: Low | C11: 0
B12: Medium | C12: 1
B13: High | C13: 2
C14: =SUM(C2:C13) -> 39

Sheet wiki
A1: Item No. | B1: Section | C1: Issue | D1: MoSCoW | E1: Issue Type (None/Bug/Rework/Enhancement) by HAESL | F1: Comments (Consolidated) | G1: Issue Raise Date | H1: Raised by | I1: Screen Capture | J1: Issue Type (None/Bug/Rework/Enhancement) by RR | K1: Priority Classification (by RR) | L1: User Story No (by RR) | M1: Comments (by RR) (Consolidated) | N1: Change Request Accepted by HAESL(For Enhancements Only) | O1: HAESL Comments (Consolidated) | P1: Comment date, Commented by | Q1: Closed/Fixed/Not yet fix | R1: Category | S1: Classification Hint | T1: Critical Priority
A2: =raw!A54 -> 42 | B2: =raw!B54 -> Planner -> Streamer -> Active Steamers | C2: =raw!C54 -> System | D2: =raw!D54 -> Must | E2: =raw!E54 -> Rework | F2: =_xlfn.TEXTJOIN(CHAR(10),TRUE,raw!F54:F55) -> Cost / DIW covers Tasks 1 to 15 only. As the inspection date is 07 Mar 2026, please confirm that the end date should be 07 Mar 2026 rather than 01 Apr 2026. | G2: =raw!G54 -> 46100 | H2: =raw!H54 -> Ricky | I2: =raw!I54 -> Refer to Screen Capture | J2: =raw!J54 -> 0 | K2: =raw!K54 -> 0 | L2: =raw!L54 -> 0 | M2: =_xlfn.TEXTJOIN(CHAR(10),TRUE,raw!M54:M55) | N2: =raw!N54 -> 0 | O2: =_xlfn.TEXTJOIN(CHAR(10),TRUE,raw!O54:O55) -> Removed | P2: =raw!P54 -> 0 | Q2: =raw!Q54 -> Closed | R2: {=_xlfn.LET(_xlpm.txt,LOWER(B2&" "&C2&" "&F2&" "&M2&" "&O2),_xlfn.IFS(OR(IFERROR(SEARCH("diw",_xlpm.txt),0)>0,IFERROR(SEARCH("cost review",_xlpm.txt),0)>0,IFERROR(SEARCH("re-induction",_xlpm.txt),0)>0,IFERROR(SEARCH("second induction",_xlpm.txt),0)>0,IFERROR(SEARCH("quotation",_xlpm.txt),0)>0),"DIW/Cost Review",OR(IFERROR(SEARCH("swap",_xlpm.txt),0)>0,IFERROR(SEARCH("off-module",_xlpm.txt),0)>0,IFERROR(SEARCH("off module",_xlpm.txt),0)>0,IFERROR(SEARCH("dispatch module",_xlpm.txt),0)>0),"Swap Module",OR(IFERROR(SEARCH("notif",_xlpm.txt),0)>0,IFERROR(SEARCH("line manager",_xlpm.txt),0)>0,IFERROR(SEARCH("reject reason",_xlpm.txt),0)>0,IFERROR(SEARCH("approval",_xlpm.txt),0)>0,IFERROR(SEARCH("approve",_xlpm.txt),0)>0),"Notification",IFERROR(SEARCH("calendar",_xlpm.txt),0)>0,"Task Owner View",OR(IFERROR(SEARCH("task owner",_xlpm.txt),0)>0,IFERROR(SEARCH("pcd",_xlpm.txt),0)>0,IFERROR(SEARCH("acd",_xlpm.txt),0)>0,IFERROR(SEARCH("actual completion",_xlpm.txt),0)>0,IFERROR(SEARCH("delay",_xlpm.txt),0)>0,IFERROR(SEARCH("task ",_xlpm.txt),0)>0,IFERROR(SEARCH("tasks",_xlpm.txt),0)>0),"Task Owner Action",TRUE,"Other / General"))} -> DIW/Cost Review | S2: {=_xlfn.LET(_xlpm.txt,LOWER(B2&" "&C2&" "&F2&" "&M2&" "&O2),_xlfn.IFS(IFERROR(SEARCH("diw",_xlpm.txt),0)>0,"diw",IFERROR(SEARCH("cost review",_xlpm.txt),0)>0,"cost review",IFERROR(SEARCH("re-induction",_xlpm.txt),0)>0,"re-induction",IFERROR(SEARCH("second induction",_xlpm.txt),0)>0,"second induction",IFERROR(SEARCH("quotation",_xlpm.txt),0)>0,"quotation",IFERROR(SEARCH("swap",_xlpm.txt),0)>0,"swap",IFERROR(SEARCH("off-module",_xlpm.txt),0)>0,"off-module",IFERROR(SEARCH("off module",_xlpm.txt),0)>0,"off module",IFERROR(SEARCH("dispatch module",_xlpm.txt),0)>0,"dispatch module",IFERROR(SEARCH("notif",_xlpm.txt),0)>0,"notification",IFERROR(SEARCH("line manager",_xlpm.txt),0)>0,"line manager",IFERROR(SEARCH("reject reason",_xlpm.txt),0)>0,"reject reason",IFERROR(SEARCH("approval",_xlpm.txt),0)>0,"approval",IFERROR(SEARCH("approve",_xlpm.txt),0)>0,"approve",IFERROR(SEARCH("calendar",_xlpm.txt),0)>0,"calendar",IFERROR(SEARCH("task owner",_xlpm.txt),0)>0,"task owner",IFERROR(SEARCH("pcd",_xlpm.txt),0)>0,"PCD",IFERROR(SEARCH("acd",_xlpm.txt),0)>0,"ACD",IFERROR(SEARCH("actual completion",_xlpm.txt),0)>0,"actual completion",IFERROR(SEARCH("delay",_xlpm.txt),0)>0,"delay",IFERROR(SEARCH("task ",_xlpm.txt),0)>0,"task",IFERROR(SEARCH("tasks",_xlpm.txt),0)>0,"tasks",TRUE,"(no match)"))} -> diw | T2: Removed
A3: =raw!A116 -> 80 | B3: =raw!B116 -> Streamer | C3: =raw!C116 -> System | D3: =raw!D116 -> Must | E3: =raw!E116 -> Bug | F3: =raw!F116 -> F08. “Edit Streamer” button FAIL, when reload a template, all previous template COMPLETED tasks data should be fill in to the NEW template | G3: =raw!G116 -> 46114 | H3: =raw!H116 -> Praveen on Ray's Behalf | ... Q3: =raw!Q116 -> 0 | R3: {=_xlfn.LET(_xlpm.txt,LOWER(B3&" "&C3&" "&F3&" "&M3&" "&O3),_xlfn.IFS(OR(IFERROR(SEARCH("diw",_xlpm.txt),0)>0,IFERROR(SEARCH("cost review",_xlpm.txt),0)>0,IFERROR(SEARCH("re-induction",_xlpm.txt),0)>0,IFERROR(SEARCH("second induction",_xlpm.txt),0)>0,IFERROR(SEARCH("quotation",_xlpm.txt),0)>0),"DIW/Cost Review",OR(IFERROR(SEARCH("swap",_xlpm.txt),0)>0,IFERROR(SEARCH("off-module",_xlpm.txt),0)>0,IFERROR(SEARCH("off module",_xlpm.txt),0)>0,IFERROR(SEARCH("dispatch module",_xlpm.txt),0)>0),"Swap Module",OR(IFERROR(SEARCH("notif",_xlpm.txt),0)>0,IFERROR(SEARCH("line manager",_xlpm.txt),0)>0,IFERROR(SEARCH("reject reason",_xlpm.txt),0)>0,IFERROR(SEARCH("approval",_xlpm.txt),0)>0,IFERROR(SEARCH("approve",_xlpm.txt),0)>0),"Notification",IFERROR(SEARCH("calendar",_xlpm.txt),0)>0,"Task Owner View",OR(IFERROR(SEARCH("task owner",_xlpm.txt),0)>0,IFERROR(SEARCH("pcd",_xlpm.txt),0)>0,IFERROR(SEARCH("acd",_xlpm.txt),0)>0,IFERROR(SEARCH("actual completion",_xlpm.txt),0)>0,IFERROR(SEARCH("delay",_xlpm.txt),0)>0,IFERROR(SEARCH("task ",_xlpm.txt),0)>0,IFERROR(SEARCH("tasks",_xlpm.txt),0)>0),"Task Owner Action",TRUE,"Other / General"))} -> DIW/Cost Review | S3: {=_xlfn.LET(_xlpm.txt,LOWER(B3&" "&C3&" "&F3&" "&M3&" "&O3),_xlfn.IFS(IFERROR(SEARCH("diw",_xlpm.txt),0)>0,"diw",IFERROR(SEARCH("cost review",_xlpm.txt),0)>0,"cost review",IFERROR(SEARCH("re-induction",_xlpm.txt),0)>0,"re-induction",IFERROR(SEARCH("second induction",_xlpm.txt),0)>0,"second induction",IFERROR(SEARCH("quotation",_xlpm.txt),0)>0,"quotation",IFERROR(SEARCH("swap",_xlpm.txt),0)>0,"swap",IFERROR(SEARCH("off-module",_xlpm.txt),0)>0,"off-module",IFERROR(SEARCH("off module",_xlpm.txt),0)>0,"off module",IFERROR(SEARCH("dispatch module",_xlpm.txt),0)>0,"dispatch module",IFERROR(SEARCH("notif",_xlpm.txt),0)>0,"notification",IFERROR(SEARCH("line manager",_xlpm.txt),0)>0,"line manager",IFERROR(SEARCH("reject reason",_xlpm.txt),0)>0,"reject reason",IFERROR(SEARCH("approval",_xlpm.txt),0)>0,"approval",IFERROR(SEARCH("approve",_xlpm.txt),0)>0,"approve",IFERROR(SEARCH("calendar",_xlpm.txt),0)>0,"calendar",IFERROR(SEARCH("task owner",_xlpm.txt),0)>0,"task owner",IFERROR(SEARCH("pcd",_xlpm.txt),0)>0,"PCD",IFERROR(SEARCH("acd",_xlpm.txt),0)>0,"ACD",IFERROR(SEARCH("actual completion",_xlpm.txt),0)>0,"actual completion",IFERROR(SEARCH("delay",_xlpm.txt),0)>0,"delay",IFERROR(SEARCH("task ",_xlpm.txt),0)>0,"task",IFERROR(SEARCH("tasks",_xlpm.txt),0)>0,"tasks",TRUE,"(no match)"))} -> re-induction | T3: High
A4: =raw!A196 -> 120 | B4: =raw!B196 -> re-induction | C4: =raw!C196 -> System | D4: =raw!D196 -> Must | E4: =raw!E196 -> Rework | F4: =raw!F196 -> DIW and cost review streamer can be re-induction day back day within 7 day | G4: =raw!G196 -> 46126 | H4: =raw!H196 -> Ray | ... Q4: =raw!Q196 -> 0 | R4: {=_xlfn.LET(_xlpm.txt,LOWER(B4&" "&C4&" "&F4&" "&M4&" "&O4),_xlfn.IFS(OR(IFERROR(SEARCH("diw",_xlpm.txt),0)>0,IFERROR(SEARCH("cost review",_xlpm.txt),0)>0,IFERROR(SEARCH("re-induction",_xlpm.txt),0)>0,IFERROR(SEARCH("second induction",_xlpm.txt),0)>0,IFERROR(SEARCH("quotation",_xlpm.txt),0)>0),"DIW/Cost Review",OR(IFERROR(SEARCH("swap",_xlpm.txt),0)>0,IFERROR(SEARCH("off-module",_xlpm.txt),0)>0,IFERROR(SEARCH("off module",_xlpm.txt),0)>0,IFERROR(SEARCH("dispatch module",_xlpm.txt),0)>0),"Swap Module",OR(IFERROR(SEARCH("notif",_xlpm.txt),0)>0,IFERROR(SEARCH("line manager",_xlpm.txt),0)>0,IFERROR(SEARCH("reject reason",_xlpm.txt),0)>0,IFERROR(SEARCH("approval",_xlpm.txt),0)>0,IFERROR(SEARCH("approve",_xlpm.txt),0)>0),"Notification",IFERROR(SEARCH("calendar",_xlpm.txt),0)>0,"Task Owner View",OR(IFERROR(SEARCH("task owner",_xlpm.txt),0)>0,IFERROR(SEARCH("pcd",_xlpm.txt),0)>0,IFERROR(SEARCH("acd",_xlpm.txt),0)>0,IFERROR(SEARCH("actual completion",_xlpm.txt),0)>0,IFERROR(SEARCH("delay",_xlpm.txt),0)>0,IFERROR(SEARCH("task ",_xlpm.txt),0)>0,IFERROR(SEARCH("tasks",_xlpm.txt),0)>0),"Task Owner Action",TRUE,"Other / General"))} -> DIW/Cost Review | S4: {=_xlfn.LET(_xlpm.txt,LOWER(B4&" "&C4&" "&F4&" "&M4&" "&O4),_xlfn.IFS(IFERROR(SEARCH("diw",_xlpm.txt),0)>0,"diw",IFERROR(SEARCH("cost review",_xlpm.txt),0)>0,"cost review",IFERROR(SEARCH("re-induction",_xlpm.txt),0)>0,"re-induction",IFERROR(SEARCH("second induction",_xlpm.txt),0)>0,"second induction",IFERROR(SEARCH("quotation",_xlpm.txt),0)>0,"quotation",IFERROR(SEARCH("swap",_xlpm.txt),0)>0,"swap",IFERROR(SEARCH("off-module",_xlpm.txt),0)>0,"off-module",IFERROR(SEARCH("off module",_xlpm.txt),0)>0,"off module",IFERROR(SEARCH("dispatch module",_xlpm.txt),0)>0,"dispatch module",IFERROR(SEARCH("notif",_xlpm.txt),0)>0,"notification",IFERROR(SEARCH("line manager",_xlpm.txt),0)>0,"line manager",IFERROR(SEARCH("reject reason",_xlpm.txt),0)>0,"reject reason",IFERROR(SEARCH("approval",_xlpm.txt),0)>0,"approval",IFERROR(SEARCH("approve",_xlpm.txt),0)>0,"approve",IFERROR(SEARCH("calendar",_xlpm.txt),0)>0,"calendar",IFERROR(SEARCH("task owner",_xlpm.txt),0)>0,"task owner",IFERROR(SEARCH("pcd",_xlpm.txt),0)>0,"PCD",IFERROR(SEARCH("acd",_xlpm.txt),0)>0,"ACD",IFERROR(SEARCH("actual completion",_xlpm.txt),0)>0,"actual completion",IFERROR(SEARCH("delay",_xlpm.txt),0)>0,"delay",IFERROR(SEARCH("task ",_xlpm.txt),0)>0,"task",IFERROR(SEARCH("tasks",_xlpm.txt),0)>0,"tasks",TRUE,"(no match)"))} -> diw | T4: Medium
A5: =raw!A212 -> 132 | B5: =raw!B212 -> DIW,cost review streamer | C5: =raw!C212 -> System | D5: =raw!D212 -> Must | E5: =raw!E212 -> Bug | F5: =_xlfn.TEXTJOIN(CHAR(10),TRUE,raw!F212:F214) -> 1. DIW completed and released, streamer then change to Cost Review and will need to capture second release date for Cost Review. 2. The DIW streamer cannot be converted to a normal streamer as non-DIW tasks are still locked (Grey Color). 3. The Cost Review streamer cannot be converted to a normal streamer as non-Cost Review tasks are still locked (Grey Color). Also the Cost Review Task data such as Finish Date, PCD & ACD should not be changed (Same as Cost Review Streamer) except for Task 4 Inducton | G5: =raw!G212 -> 46128 | H5: =raw!H212 -> Ricky | I5: =raw!I212 -> 0 | J5: =raw!J212 -> 0 | K5: =raw!K212 -> 0 | L5: =raw!L212 -> 0 | M5: =_xlfn.TEXTJOIN(CHAR(10),TRUE,raw!M212:M214) | N5: =raw!N212 -> 0 | O5: =_xlfn.TEXTJOIN(CHAR(10),TRUE,raw!O212:O214) -> High | P5: =raw!P212 -> 0 | Q5: =raw!Q212 -> 0 | R5: {=_xlfn.LET(_xlpm.txt,LOWER(B5&" "&C5&" "&F5&" "&M5&" "&O5),_xlfn.IFS(OR(IFERROR(SEARCH("diw",_xlpm.txt),0)>0,IFERROR(SEARCH("cost review",_xlpm.txt),0)>0,IFERROR(SEARCH("re-induction",_xlpm.txt),0)>0,IFERROR(SEARCH("second induction",_xlpm.txt),0)>0,IFERROR(SEARCH("quotation",_xlpm.txt),0)>0),"DIW/Cost Review",OR(IFERROR(SEARCH("swap",_xlpm.txt),0)>0,IFERROR(SEARCH("off-module",_xlpm.txt),0)>0,IFERROR(SEARCH("off module",_xlpm.txt),0)>0,IFERROR(SEARCH("dispatch module",_xlpm.txt),0)>0),"Swap Module",OR(IFERROR(SEARCH("notif",_xlpm.txt),0)>0,IFERROR(SEARCH("line manager",_xlpm.txt),0)>0,IFERROR(SEARCH("reject reason",_xlpm.txt),0)>0,IFERROR(SEARCH("approval",_xlpm.txt),0)>0,IFERROR(SEARCH("approve",_xlpm.txt),0)>0),"Notification",IFERROR(SEARCH("calendar",_xlpm.txt),0)>0,"Task Owner View",OR(IFERROR(SEARCH("task owner",_xlpm.txt),0)>0,IFERROR(SEARCH("pcd",_xlpm.txt),0)>0,IFERROR(SEARCH("acd",_xlpm.txt),0)>0,IFERROR(SEARCH("actual completion",_xlpm.txt),0)>0,IFERROR(SEARCH("delay",_xlpm.txt),0)>0,IFERROR(SEARCH("task ",_xlpm.txt),0)>0,IFERROR(SEARCH("tasks",_xlpm.txt),0)>0),"Task Owner Action",TRUE,"Other / General"))} -> DIW/Cost Review | S5: {=_xlfn.LET(_xlpm.txt,LOWER(B5&" "&C5&" "&F5&" "&M5&" "&O5),_xlfn.IFS(IFERROR(SEARCH("diw",_xlpm.txt),0)>0,"diw",IFERROR(SEARCH("cost review",_xlpm.txt),0)>0,"cost review",IFERROR(SEARCH("re-induction",_xlpm.txt),0)>0,"re-induction",IFERROR(SEARCH("second induction",_xlpm.txt),0)>0,"second induction",IFERROR(SEARCH("quotation",_xlpm.txt),0)>0,"quotation",IFERROR(SEARCH("swap",_xlpm.txt),0)>0,"swap",IFERROR(SEARCH("off-module",_xlpm.txt),0)>0,"off-module",IFERROR(SEARCH("off module",_xlpm.txt),0)>0,"off module",IFERROR(SEARCH("dispatch module",_xlpm.txt),0)>0,"dispatch module",IFERROR(SEARCH("notif",_xlpm.txt),0)>0,"notification",IFERROR(SEARCH("line manager",_xlpm.txt),0)>0,"line manager",IFERROR(SEARCH("reject reason",_xlpm.txt),0)>0,"reject reason",IFERROR(SEARCH("approval",_xlpm.txt),0)>0,"approval",IFERROR(SEARCH("approve",_xlpm.txt),0)>0,"approve",IFERROR(SEARCH("calendar",_xlpm.txt),0)>0,"calendar",IFERROR(SEARCH("task owner",_xlpm.txt),0)>0,"task owner",IFERROR(SEARCH("pcd",_xlpm.txt),0)>0,"PCD",IFERROR(SEARCH("acd",_xlpm.txt),0)>0,"ACD",IFERROR(SEARCH("actual completion",_xlpm.txt),0)>0,"actual completion",IFERROR(SEARCH("delay",_xlpm.txt),0)>0,"delay",IFERROR(SEARCH("task ",_xlpm.txt),0)>0,"task",IFERROR(SEARCH("tasks",_xlpm.txt),0)>0,"tasks",TRUE,"(no match)"))} -> diw | T5: High
A6: =raw!A6 -> 4 | B6: =raw!B6 -> Notification | C6: =raw!C6 -> System | D6: =raw!D6 -> Must | E6: =raw!E6 -> Bug | F6: =raw!F6 -> Unable to clear notifcations from notifcation list. After clicking the "X", the same notifcation will pop up again later, all the notifications become accumulate as a huge list. | G6: =raw!G6 -> 46097 | H6: =raw!H6 -> Ray | ... Q6: =raw!Q6 -> Fixed | R6: {=_xlfn.LET(_xlpm.txt,LOWER(B6&" "&C6&" "&F6&" "&M6&" "&O6),_xlfn.IFS(OR(IFERROR(SEARCH("diw",_xlpm.txt),0)>0,IFERROR(SEARCH("cost review",_xlpm.txt),0)>0,IFERROR(SEARCH("re-induction",_xlpm.txt),0)>0,IFERROR(SEARCH("second induction",_xlpm.txt),0)>0,IFERROR(SEARCH("quotation",_xlpm.txt),0)>0),"DIW/Cost Review",OR(IFERROR(SEARCH("swap",_xlpm.txt),0)>0,IFERROR(SEARCH("off-module",_xlpm.txt),0)>0,IFERROR(SEARCH("off module",_xlpm.txt),0)>0,IFERROR(SEARCH("dispatch module",_xlpm.txt),0)>0),"Swap Module",OR(IFERROR(SEARCH("notif",_xlpm.txt),0)>0,IFERROR(SEARCH("line manager",_xlpm.txt),0)>0,IFERROR(SEARCH("reject reason",_xlpm.txt),0)>0,IFERROR(SEARCH("approval",_xlpm.txt),0)>0,IFERROR(SEARCH("approve",_xlpm.txt),0)>0),"Notification",IFERROR(SEARCH("calendar",_xlpm.txt),0)>0,"Task Owner View",OR(IFERROR(SEARCH("task owner",_xlpm.txt),0)>0,IFERROR(SEARCH("pcd",_xlpm.txt),0)>0,IFERROR(SEARCH("acd",_xlpm.txt),0)>0,IFERROR(SEARCH("actual completion",_xlpm.txt),0)>0,IFERROR(SEARCH("delay",_xlpm.txt),0)>0,IFERROR(SEARCH("task ",_xlpm.txt),0)>0,IFERROR(SEARCH("tasks",_xlpm.txt),0)>0),"Task Owner Action",TRUE,"Other / General"))} -> Notification | S6: {=_xlfn.LET(_xlpm.txt,LOWER(B6&" "&C6&" "&F6&" "&M6&" "&O6),_xlfn.IFS(IFERROR(SEARCH("diw",_xlpm.txt),0)>0,"diw",IFERROR(SEARCH("cost review",_xlpm.txt),0)>0,"cost review",IFERROR(SEARCH("re-induction",_xlpm.txt),0)>0,"re-induction",IFERROR(SEARCH("second induction",_xlpm.txt),0)>0,"second induction",IFERROR(SEARCH("quotation",_xlpm.txt),0)>0,"quotation",IFERROR(SEARCH("swap",_xlpm.txt),0)>0,"swap",IFERROR(SEARCH("off-module",_xlpm.txt),0)>0,"off-module",IFERROR(SEARCH("off module",_xlpm.txt),0)>0,"off module",IFERROR(SEARCH("dispatch module",_xlpm.txt),0)>0,"dispatch module",IFERROR(SEARCH("notif",_xlpm.txt),0)>0,"notification",IFERROR(SEARCH("line manager",_xlpm.txt),0)>0,"line manager",IFERROR(SEARCH("reject reason",_xlpm.txt),0)>0,"reject reason",IFERROR(SEARCH("approval",_xlpm.txt),0)>0,"approval",IFERROR(SEARCH("approve",_xlpm.txt),0)>0,"approve",IFERROR(SEARCH("calendar",_xlpm.txt),0)>0,"calendar",IFERROR(SEARCH("task owner",_xlpm.txt),0)>0,"task owner",IFERROR(SEARCH("pcd",_xlpm.txt),0)>0,"PCD",IFERROR(SEARCH("acd",_xlpm.txt),0)>0,"ACD",IFERROR(SEARCH("actual completion",_xlpm.txt),0)>0,"actual completion",IFERROR(SEARCH("delay",_xlpm.txt),0)>0,"delay",IFERROR(SEARCH("task ",_xlpm.txt),0)>0,"task",IFERROR(SEARCH("tasks",_xlpm.txt),0)>0,"tasks",TRUE,"(no match)"))} -> notification | T6: Low
A7: =raw!A15 -> 13 | B7: =raw!B15 -> Planner - Tasks | C7: =raw!C15 -> System | D7: =raw!D15 -> Must | E7: =raw!E15 -> Bug | F7: =_xlfn.TEXTJOIN(CHAR(10),TRUE,raw!F15:F17) -> Update Task 4 Finish Date: 1. 41500 was created on 17 Mar 2026, and Task 4 actual completion date is 17 Mar 2026; however, it is currently showing as 16 Mar 2026. 2. Unable to select “Cancel for Approval.” | G7: =raw!G15 -> 46097 | H7: =raw!H15 -> Ricky | I7: =raw!I15 -> Refer to Screen Capture | J7: =raw!J15 -> None | K7: =raw!K15 -> 0 | L7: =raw!L15 -> 0 | M7: =_xlfn.TEXTJOIN(CHAR(10),TRUE,raw!M15:M17) -> Dev to reproduce issue | N7: =raw!N15 -> 0 | O7: =_xlfn.TEXTJOIN(CHAR(10),TRUE,raw!O15:O17) -> Low, fixed | P7: =raw!P15 -> 0 | Q7: =raw!Q15 -> Fixed | R7: {=_xlfn.LET(_xlpm.txt,LOWER(B7&" "&C7&" "&F7&" "&M7&" "&O7),_xlfn.IFS(OR(IFERROR(SEARCH("diw",_xlpm.txt),0)>0,IFERROR(SEARCH("cost review",_xlpm.txt),0)>0,IFERROR(SEARCH("re-induction",_xlpm.txt),0)>0,IFERROR(SEARCH("second induction",_xlpm.txt),0)>0,IFERROR(SEARCH("quotation",_xlpm.txt),0)>0),"DIW/Cost Review",OR(IFERROR(SEARCH("swap",_xlpm.txt),0)>0,IFERROR(SEARCH("off-module",_xlpm.txt),0)>0,IFERROR(SEARCH("off module",_xlpm.txt),0)>0,IFERROR(SEARCH("dispatch module",_xlpm.txt),0)>0),"Swap Module",OR(IFERROR(SEARCH("notif",_xlpm.txt),0)>0,IFERROR(SEARCH("line manager",_xlpm.txt),0)>0,IFERROR(SEARCH("reject reason",_xlpm.txt),0)>0,IFERROR(SEARCH("approval",_xlpm.txt),0)>0,IFERROR(SEARCH("approve",_xlpm.txt),0)>0),"Notification",IFERROR(SEARCH("calendar",_xlpm.txt),0)>0,"Task Owner View",OR(IFERROR(SEARCH("task owner",_xlpm.txt),0)>0,IFERROR(SEARCH("pcd",_xlpm.txt),0)>0,IFERROR(SEARCH("acd",_xlpm.txt),0)>0,IFERROR(SEARCH("actual completion",_xlpm.txt),0)>0,IFERROR(SEARCH("delay",_xlpm.txt),0)>0,IFERROR(SEARCH("task ",_xlpm.txt),0)>0,IFERROR(SEARCH("tasks",_xlpm.txt),0)>0),"Task Owner Action",TRUE,"Other / General"))} -> Notification | S7: {=_xlfn.LET(_xlpm.txt,LOWER(B7&" "&C7&" "&F7&" "&M7&" "&O7),_xlfn.IFS(IFERROR(SEARCH("diw",_xlpm.txt),0)>0,"diw",IFERROR(SEARCH("cost review",_xlpm.txt),0)>0,"cost review",IFERROR(SEARCH("re-induction",_xlpm.txt),0)>0,"re-induction",IFERROR(SEARCH("second induction",_xlpm.txt),0)>0,"second induction",IFERROR(SEARCH("quotation",_xlpm.txt),0)>0,"quotation",IFERROR(SEARCH("swap",_xlpm.txt),0)>0,"swap",IFERROR(SEARCH("off-module",_xlpm.txt),0)>0,"off-module",IFERROR(SEARCH("off module",_xlpm.txt),0)>0,"off module",IFERROR(SEARCH("dispatch module",_xlpm.txt),0)>0,"dispatch module",IFERROR(SEARCH("notif",_xlpm.txt),0)>0,"notification",IFERROR(SEARCH("line manager",_xlpm.txt),0)>0,"line manager",IFERROR(SEARCH("reject reason",_xlpm.txt),0)>0,"reject reason",IFERROR(SEARCH("approval",_xlpm.txt),0)>0,"approval",IFERROR(SEARCH("approve",_xlpm.txt),0)>0,"approve",IFERROR(SEARCH("calendar",_xlpm.txt),0)>0,"calendar",IFERROR(SEARCH("task owner",_xlpm.txt),0)>0,"task owner",IFERROR(SEARCH("pcd",_xlpm.txt),0)>0,"PCD",IFERROR(SEARCH("acd",_xlpm.txt),0)>0,"ACD",IFERROR(SEARCH("actual completion",_xlpm.txt),0)>0,"actual completion",IFERROR(SEARCH("delay",_xlpm.txt),0)>0,"delay",IFERROR(SEARCH("task ",_xlpm.txt),0)>0,"task",IFERROR(SEARCH("tasks",_xlpm.txt),0)>0,"tasks",TRUE,"(no match)"))} -> approval | T7: Low
A8: =raw!A18 -> 14 | B8: =raw!B18 -> Planner - Tasks | C8: =raw!C18 -> System | D8: =raw!D18 -> Must | E8: =raw!E18 -> Bug | F8: =_xlfn.TEXTJOIN(CHAR(10),TRUE,raw!F18:F20) -> Update Task 4 Finish Date: Job 21231 was completed on 17 May 2026. The completion date was entered as 16 Mar 2026; however, it is not reflected under “Actual Completion.” 2. Unable to select “Cancel for Approval.” | G8: =raw!G18 -> 46097 | H8: =raw!H18 -> Ricky | I8: =raw!I18 -> Refer to Screen Capture | J8: =raw!J18 -> None | K8: =raw!K18 -> 0 | L8: =raw!L18 -> 0 | M8: =_xlfn.TEXTJOIN(CHAR(10),TRUE,raw!M18:M20) -> Dev to reproduce issue | N8: =raw!N18 -> 0 | O8: =_xlfn.TEXTJOIN(CHAR(10),TRUE,raw!O18:O20) -> high, operational risk | P8: =raw!P18 -> 0 | Q8: =raw!Q18 -> Not yet fix | R8: {=_xlfn.LET(_xlpm.txt,LOWER(B8&" "&C8&" "&F8&" "&M8&" "&O8),_xlfn.IFS(OR(IFERROR(SEARCH("diw",_xlpm.txt),0)>0,IFERROR(SEARCH("cost review",_xlpm.txt),0)>0,IFERROR(SEARCH("re-induction",_xlpm.txt),0)>0,IFERROR(SEARCH("second induction",_xlpm.txt),0)>0,IFERROR(SEARCH("quotation",_xlpm.txt),0)>0),"DIW/Cost Review",OR(IFERROR(SEARCH("swap",_xlpm.txt),0)>0,IFERROR(SEARCH("off-module",_xlpm.txt),0)>0,IFERROR(SEARCH("off module",_xlpm.txt),0)>0,IFERROR(SEARCH("dispatch module",_xlpm.txt),0)>0),"Swap Module",OR(IFERROR(SEARCH("notif",_xlpm.txt),0)>0,IFERROR(SEARCH("line manager",_xlpm.txt),0)>0,IFERROR(SEARCH("reject reason",_xlpm.txt),0)>0,IFERROR(SEARCH("approval",_xlpm.txt),0)>0,IFERROR(SEARCH("approve",_xlpm.txt),0)>0),"Notification",IFERROR(SEARCH("calendar",_xlpm.txt),0)>0,"Task Owner View",OR(IFERROR(SEARCH("task owner",_xlpm.txt),0)>0,IFERROR(SEARCH("pcd",_xlpm.txt),0)>0,IFERROR(SEARCH("acd",_xlpm.txt),0)>0,IFERROR(SEARCH("actual completion",_xlpm.txt),0)>0,IFERROR(SEARCH("delay",_xlpm.txt),0)>0,IFERROR(SEARCH("task ",_xlpm.txt),0)>0,IFERROR(SEARCH("tasks",_xlpm.txt),0)>0),"Task Owner Action",TRUE,"Other / General"))} -> Notification | S8: {=_xlfn.LET(_xlpm.txt,LOWER(B8&" "&C8&" "&F8&" "&M8&" "&O8),_xlfn.IFS(IFERROR(SEARCH("diw",_xlpm.txt),0)>0,"diw",IFERROR(SEARCH("cost review",_xlpm.txt),0)>0,"cost review",IFERROR(SEARCH("re-induction",_xlpm.txt),0)>0,"re-induction",IFERROR(SEARCH("second induction",_xlpm.txt),0)>0,"second induction",IFERROR(SEARCH("quotation",_xlpm.txt),0)>0,"quotation",IFERROR(SEARCH("swap",_xlpm.txt),0)>0,"swap",IFERROR(SEARCH("off-module",_xlpm.txt),0)>0,"off-module",IFERROR(SEARCH("off module",_xlpm.txt),0)>0,"off module",IFERROR(SEARCH("dispatch module",_xlpm.txt),0)>0,"dispatch module",IFERROR(SEARCH("notif",_xlpm.txt),0)>0,"notification",IFERROR(SEARCH("line manager",_xlpm.txt),0)>0,"line manager",IFERROR(SEARCH("reject reason",_xlpm.txt),0)>0,"reject reason",IFERROR(SEARCH("approval",_xlpm.txt),0)>0,"approval",IFERROR(SEARCH("approve",_xlpm.txt),0)>0,"approve",IFERROR(SEARCH("calendar",_xlpm.txt),0)>0,"calendar",IFERROR(SEARCH("task owner",_xlpm.txt),0)>0,"task owner",IFERROR(SEARCH("pcd",_xlpm.txt),0)>0,"PCD",IFERROR(SEARCH("acd",_xlpm.txt),0)>0,"ACD",IFERROR(SEARCH("actual completion",_xlpm.txt),0)>0,"actual completion",IFERROR(SEARCH("delay",_xlpm.txt),0)>0,"delay",IFERROR(SEARCH("task ",_xlpm.txt),0)>0,"task",IFERROR(SEARCH("tasks",_xlpm.txt),0)>0,"tasks",TRUE,"(no match)"))} -> approval | T8: high
A9: =raw!A21 -> 15 | B9: =raw!B21 -> Notification - Line Manager | C9: =raw!C21 -> System | D9: =raw!D21 -> Must | E9: =raw!E21 -> Bug | F9: =raw!F21 -> No items in the line manager notification list even there are few items are pending approval | G9: =raw!G21 -> 46098 | H9: =raw!H21 -> Ray | ... Q9: =raw!Q21 -> Not yet fix | R9: {=_xlfn.LET(_xlpm.txt,LOWER(B9&" "&C9&" "&F9&" "&M9&" "&O9),_xlfn.IFS(OR(IFERROR(SEARCH("diw",_xlpm.txt),0)>0,IFERROR(SEARCH("cost review",_xlpm.txt),0)>0,IFERROR(SEARCH("re-induction",_xlpm.txt),0)>0,IFERROR(SEARCH("second induction",_xlpm.txt),0)>0,IFERROR(SEARCH("quotation",_xlpm.txt),0)>0),"DIW/Cost Review",OR(IFERROR(SEARCH("swap",_xlpm.txt),0)>0,IFERROR(SEARCH("off-module",_xlpm.txt),0)>0,IFERROR(SEARCH("off module",_xlpm.txt),0)>0,IFERROR(SEARCH("dispatch module",_xlpm.txt),0)>0),"Swap Module",OR(IFERROR(SEARCH("notif",_xlpm.txt),0)>0,IFERROR(SEARCH("line manager",_xlpm.txt),0)>0,IFERROR(SEARCH("reject reason",_xlpm.txt),0)>0,IFERROR(SEARCH("approval",_xlpm.txt),0)>0,IFERROR(SEARCH("approve",_xlpm.txt),0)>0),"Notification",IFERROR(SEARCH("calendar",_xlpm.txt),0)>0,"Task Owner View",OR(IFERROR(SEARCH("task owner",_xlpm.txt),0)>0,IFERROR(SEARCH("pcd",_xlpm.txt),0)>0,IFERROR(SEARCH("acd",_xlpm.txt),0)>0,IFERROR(SEARCH("actual completion",_xlpm.txt),0)>0,IFERROR(SEARCH("delay",_xlpm.txt),0)>0,IFERROR(SEARCH("task ",_xlpm.txt),0)>0,IFERROR(SEARCH("tasks",_xlpm.txt),0)>0),"Task Owner Action",TRUE,"Other / General"))} -> Notification | S9: {=_xlfn.LET(_xlpm.txt,LOWER(B9&" "&C9&" "&F9&" "&M9&" "&O9),_xlfn.IFS(IFERROR(SEARCH("diw",_xlpm.txt),0)>0,"diw",IFERROR(SEARCH("cost review",_xlpm.txt),0)>0,"cost review",IFERROR(SEARCH("re-induction",_xlpm.txt),0)>0,"re-induction",IFERROR(SEARCH("second induction",_xlpm.txt),0)>0,"second induction",IFERROR(SEARCH("quotation",_xlpm.txt),0)>0,"quotation",IFERROR(SEARCH("swap",_xlpm.txt),0)>0,"swap",IFERROR(SEARCH("off-module",_xlpm.txt),0)>0,"off-module",IFERROR(SEARCH("off module",_xlpm.txt),0)>0,"off module",IFERROR(SEARCH("dispatch module",_xlpm.txt),0)>0,"dispatch module",IFERROR(SEARCH("notif",_xlpm.txt),0)>0,"notification",IFERROR(SEARCH("line manager",_xlpm.txt),0)>0,"line manager",IFERROR(SEARCH("reject reason",_xlpm.txt),0)>0,"reject reason",IFERROR(SEARCH("approval",_xlpm.txt),0)>0,"approval",IFERROR(SEARCH("approve",_xlpm.txt),0)>0,"approve",IFERROR(SEARCH("calendar",_xlpm.txt),0)>0,"calendar",IFERROR(SEARCH("task owner",_xlpm.txt),0)>0,"task owner",IFERROR(SEARCH("pcd",_xlpm.txt),0)>0,"PCD",IFERROR(SEARCH("acd",_xlpm.txt),0)>0,"ACD",IFERROR(SEARCH("actual completion",_xlpm.txt),0)>0,"actual completion",IFERROR(SEARCH("delay",_xlpm.txt),0)>0,"delay",IFERROR(SEARCH("task ",_xlpm.txt),0)>0,"task",IFERROR(SEARCH("tasks",_xlpm.txt),0)>0,"tasks",TRUE,"(no match)"))} -> notification | T9: high
A10: =raw!A27 -> 20 | B10: =raw!B27 -> Notification | C10: =raw!C27 -> System | D10: =raw!D27 -> Must | E10: =raw!E27 -> Bug | F10: =raw!F27 -> The hour counting is incorrect | G10: =raw!G27 -> 46098 | H10: =raw!H27 -> Ray | ... Q10: =raw!Q27 -> Fixed | R10: {=_xlfn.LET(_xlpm.txt,LOWER(B10&" "&C10&" "&F10&" "&M10&" "&O10),_xlfn.IFS(OR(IFERROR(SEARCH("diw",_xlpm.txt),0)>0,IFERROR(SEARCH("cost review",_xlpm.txt),0)>0,IFERROR(SEARCH("re-induction",_xlpm.txt),0)>0,IFERROR(SEARCH("second induction",_xlpm.txt),0)>0,IFERROR(SEARCH("quotation",_xlpm.txt),0)>0),"DIW/Cost Review",OR(IFERROR(SEARCH("swap",_xlpm.txt),0)>0,IFERROR(SEARCH("off-module",_xlpm.txt),0)>0,IFERROR(SEARCH("off module",_xlpm.txt),0)>0,IFERROR(SEARCH("dispatch module",_xlpm.txt),0)>0),"Swap Module",OR(IFERROR(SEARCH("notif",_xlpm.txt),0)>0,IFERROR(SEARCH("line manager",_xlpm.txt),0)>0,IFERROR(SEARCH("reject reason",_xlpm.txt),0)>0,IFERROR(SEARCH("approval",_xlpm.txt),0)>0,IFERROR(SEARCH("approve",_xlpm.txt),0)>0),"Notification",IFERROR(SEARCH("calendar",_xlpm.txt),0)>0,"Task Owner View",OR(IFERROR(SEARCH("task owner",_xlpm.txt),0)>0,IFERROR(SEARCH("pcd",_xlpm.txt),0)>0,IFERROR(SEARCH("acd",_xlpm.txt),0)>0,IFERROR(SEARCH("actual completion",_xlpm.txt),0)>0,IFERROR(SEARCH("delay",_xlpm.txt),0)>0,IFERROR(SEARCH("task ",_xlpm.txt),0)>0,IFERROR(SEARCH("tasks",_xlpm.txt),0)>0),"Task Owner Action",TRUE,"Other / General"))} -> Notification | S10: {=_xlfn.LET(_xlpm.txt,LOWER(B10&" "&C10&" "&F10&" "&M10&" "&O10),_xlfn.IFS(IFERROR(SEARCH("diw",_xlpm.txt),0)>0,"diw",IFERROR(SEARCH("cost review",_xlpm.txt),0)>0,"cost review",IFERROR(SEARCH("re-induction",_xlpm.txt),0)>0,"re-induction",IFERROR(SEARCH("second induction",_xlpm.txt),0)>0,"second induction",IFERROR(SEARCH("quotation",_xlpm.txt),0)>0,"quotation",IFERROR(SEARCH("swap",_xlpm.txt),0)>0,"swap",IFERROR(SEARCH("off-module",_xlpm.txt),0)>0,"off-module",IFERROR(SEARCH("off module",_xlpm.txt),0)>0,"off module",IFERROR(SEARCH("dispatch module",_xlpm.txt),0)>0,"dispatch module",IFERROR(SEARCH("notif",_xlpm.txt),0)>0,"notification",IFERROR(SEARCH("line manager",_xlpm.txt),0)>0,"line manager",IFERROR(SEARCH("reject reason",_xlpm.txt),0)>0,"reject reason",IFERROR(SEARCH("approval",_xlpm.txt),0)>0,"approval",IFERROR(SEARCH("approve",_xlpm.txt),0)>0,"approve",IFERROR(SEARCH("calendar",_xlpm.txt),0)>0,"calendar",IFERROR(SEARCH("task owner",_xlpm.txt),0)>0,"task owner",IFERROR(SEARCH("pcd",_xlpm.txt),0)>0,"PCD",IFERROR(SEARCH("acd",_xlpm.txt),0)>0,"ACD",IFERROR(SEARCH("actual completion",_xlpm.txt),0)>0,"actual completion",IFERROR(SEARCH("delay",_xlpm.txt),0)>0,"delay",IFERROR(SEARCH("task ",_xlpm.txt),0)>0,"task",IFERROR(SEARCH("tasks",_xlpm.txt),0)>0,"tasks",TRUE,"(no match)"))} -> notification | T10: Low
A11: =raw!A31 -> 24 | B11: =raw!B31 -> Notification - Line Manager | C11: =raw!C31 -> System | D11: =raw!D31 -> Must | E11: =raw!E31 -> Bug | F11: =raw!F31 -> When I click Accept on an approval task, the approvals list does not refresh immediately to remove the task card. I have to close and reopen the list to see the update. In addition, the task continues to display “Pending for approval”. | G11: =raw!G31 -> 46098 | H11: =raw!H31 -> Ray | ... Q11: =raw!Q31 -> Fixed | R11: {=_xlfn.LET(_xlpm.txt,LOWER(B11&" "&C11&" "&F11&" "&M11&" "&O11),_xlfn.IFS(OR(IFERROR(SEARCH("diw",_xlpm.txt),0)>0,IFERROR(SEARCH("cost review",_xlpm.txt),0)>0,IFERROR(SEARCH("re-induction",_xlpm.txt),0)>0,IFERROR(SEARCH("second induction",_xlpm.txt),0)>0,IFERROR(SEARCH("quotation",_xlpm.txt),0)>0),"DIW/Cost Review",OR(IFERROR(SEARCH("swap",_xlpm.txt),0)>0,IFERROR(SEARCH("off-module",_xlpm.txt),0)>0,IFERROR(SEARCH("off module",_xlpm.txt),0)>0,IFERROR(SEARCH("dispatch module",_xlpm.txt),0)>0),"Swap Module",OR(IFERROR(SEARCH("notif",_xlpm.txt),0)>0,IFERROR(SEARCH("line manager",_xlpm.txt),0)>0,IFERROR(SEARCH("reject reason",_xlpm.txt),0)>0,IFERROR(SEARCH("approval",_xlpm.txt),0)>0,IFERROR(SEARCH("approve",_xlpm.txt),0)>0),"Notification",IFERROR(SEARCH("calendar",_xlpm.txt),0)>0,"Task Owner View",OR(IFERROR(SEARCH("task owner",_xlpm.txt),0)>0,IFERROR(SEARCH("pcd",_xlpm.txt),0)>0,IFERROR(SEARCH("acd",_xlpm.txt),0)>0,IFERROR(SEARCH("actual completion",_xlpm.txt),0)>0,IFERROR(SEARCH("delay",_xlpm.txt),0)>0,IFERROR(SEARCH("task ",_xlpm.txt),0)>0,IFERROR(SEARCH("tasks",_xlpm.txt),0)>0),"Task Owner Action",TRUE,"Other / General"))} -> Notification | S11: {=_xlfn.LET(_xlpm.txt,LOWER(B11&" "&C11&" "&F11&" "&M11&" "&O11),_xlfn.IFS(IFERROR(SEARCH("diw",_xlpm.txt),0)>0,"diw",IFERROR(SEARCH("cost review",_xlpm.txt),0)>0,"cost review",IFERROR(SEARCH("re-induction",_xlpm.txt),0)>0,"re-induction",IFERROR(SEARCH("second induction",_xlpm.txt),0)>0,"second induction",IFERROR(SEARCH("quotation",_xlpm.txt),0)>0,"quotation",IFERROR(SEARCH("swap",_xlpm.txt),0)>0,"swap",IFERROR(SEARCH("off-module",_xlpm.txt),0)>0,"off-module",IFERROR(SEARCH("off module",_xlpm.txt),0)>0,"off module",IFERROR(SEARCH("dispatch module",_xlpm.txt),0)>0,"dispatch module",IFERROR(SEARCH("notif",_xlpm.txt),0)>0,"notification",IFERROR(SEARCH("line manager",_xlpm.txt),0)>0,"line manager",IFERROR(SEARCH("reject reason",_xlpm.txt),0)>0,"reject reason",IFERROR(SEARCH("approval",_xlpm.txt),0)>0,"approval",IFERROR(SEARCH("approve",_xlpm.txt),0)>0,"approve",IFERROR(SEARCH("calendar",_xlpm.txt),0)>0,"calendar",IFERROR(SEARCH("task owner",_xlpm.txt),0)>0,"task owner",IFERROR(SEARCH("pcd",_xlpm.txt),0)>0,"PCD",IFERROR(SEARCH("acd",_xlpm.txt),0)>0,"ACD",IFERROR(SEARCH("actual completion",_xlpm.txt),0)>0,"actual completion",IFERROR(SEARCH("delay",_xlpm.txt),0)>0,"delay",IFERROR(SEARCH("task ",_xlpm.txt),0)>0,"task",IFERROR(SEARCH("tasks",_xlpm.txt),0)>0,"tasks",TRUE,"(no match)"))} -> notification | T11: medium
A12: =raw!A32 -> 25 | B12: =raw!B32 -> Tasks | C12: =raw!C32 -> System | D12: =raw!D32 -> Must | E12: =raw!E32 -> Bug | F12: =raw!F32 -> Unable to cancel for approval when click "Cancel for Approval" button | G12: =raw!G32 -> 46098 | H12: =raw!H32 -> Ray | ... Q12: =raw!Q32 -> Not yet fix | R12: {=_xlfn.LET(_xlpm.txt,LOWER(B12&" "&C12&" "&F12&" "&M12&" "&O12),_xlfn.IFS(OR(IFERROR(SEARCH("diw",_xlpm.txt),0)>0,IFERROR(SEARCH("cost review",_xlpm.txt),0)>0,IFERROR(SEARCH("re-induction",_xlpm.txt),0)>0,IFERROR(SEARCH("second induction",_xlpm.txt),0)>0,IFERROR(SEARCH("quotation",_xlpm.txt),0)>0),"DIW/Cost Review",OR(IFERROR(SEARCH("swap",_xlpm.txt),0)>0,IFERROR(SEARCH("off-module",_xlpm.txt),0)>0,IFERROR(SEARCH("off module",_xlpm.txt),0)>0,IFERROR(SEARCH("dispatch module",_xlpm.txt),0)>0),"Swap Module",OR(IFERROR(SEARCH("notif",_xlpm.txt),0)>0,IFERROR(SEARCH("line manager",_xlpm.txt),0)>0,IFERROR(SEARCH("reject reason",_xlpm.txt),0)>0,IFERROR(SEARCH("approval",_xlpm.txt),0)>0,IFERROR(SEARCH("approve",_xlpm.txt),0)>0),"Notification",IFERROR(SEARCH("calendar",_xlpm.txt),0)>0,"Task Owner View",OR(IFERROR(SEARCH("task owner",_xlpm.txt),0)>0,IFERROR(SEARCH("pcd",_xlpm.txt),0)>0,IFERROR(SEARCH("acd",_xlpm.txt),0)>0,IFERROR(SEARCH("actual completion",_xlpm.txt),0)>0,IFERROR(SEARCH("delay",_xlpm.txt),0)>0,IFERROR(SEARCH("task ",_xlpm.txt),0)>0,IFERROR(SEARCH("tasks",_xlpm.txt),0)>0),"Task Owner Action",TRUE,"Other / General"))} -> Notification | S12: {=_xlfn.LET(_xlpm.txt,LOWER(B12&" "&C12&" "&F12&" "&M12&" "&O12),_xlfn.IFS(IFERROR(SEARCH("diw",_xlpm.txt),0)>0,"diw",IFERROR(SEARCH("cost review",_xlpm.txt),0)>0,"cost review",IFERROR(SEARCH("re-induction",_xlpm.txt),0)>0,"re-induction",IFERROR(SEARCH("second induction",_xlpm.txt),0)>0,"second induction",IFERROR(SEARCH("quotation",_xlpm.txt),0)>0,"quotation",IFERROR(SEARCH("swap",_xlpm.txt),0)>0,"swap",IFERROR(SEARCH("off-module",_xlpm.txt),0)>0,"off-module",IFERROR(SEARCH("off module",_xlpm.txt),0)>0,"off module",IFERROR(SEARCH("dispatch module",_xlpm.txt),0)>0,"dispatch module",IFERROR(SEARCH("notif",_xlpm.txt),0)>0,"notification",IFERROR(SEARCH("line manager",_xlpm.txt),0)>0,"line manager",IFERROR(SEARCH("reject reason",_xlpm.txt),0)>0,"reject reason",IFERROR(SEARCH("approval",_xlpm.txt),0)>0,"approval",IFERROR(SEARCH("approve",_xlpm.txt),0)>0,"approve",IFERROR(SEARCH("calendar",_xlpm.txt),0)>0,"calendar",IFERROR(SEARCH("task owner",_xlpm.txt),0)>0,"task owner",IFERROR(SEARCH("pcd",_xlpm.txt),0)>0,"PCD",IFERROR(SEARCH("acd",_xlpm.txt),0)>0,"ACD",IFERROR(SEARCH("actual completion",_xlpm.txt),0)>0,"actual completion",IFERROR(SEARCH("delay",_xlpm.txt),0)>0,"delay",IFERROR(SEARCH("task ",_xlpm.txt),0)>0,"task",IFERROR(SEARCH("tasks",_xlpm.txt),0)>0,"tasks",TRUE,"(no match)"))} -> approval | T12: High
A13: =raw!A38 -> 31 | B13: =raw!B38 -> Tasks - Approval Process | C13: =raw!C38 -> System | D13: =raw!D38 -> Must | E13: =raw!E38 -> Bug | F13: =_xlfn.TEXTJOIN(CHAR(10),TRUE,raw!F38:F39) -> The list of pending approval tasks do not align with the actual pending approval task | G13: =raw!G38 -> 46099 | H13: =raw!H38 -> Ray | I13: =raw!I38 -> Refer to Screen Capture | J13: =raw!J38 -> Bug | K13: =raw!K38 -> P4 | L13: =raw!L38 -> 0 | M13: =_xlfn.TEXTJOIN(CHAR(10),TRUE,raw!M38:M39) -> Needs to be addressed | N13: =raw!N38 -> 0 | O13: =_xlfn.TEXTJOIN(CHAR(10),TRUE,raw!O38:O39) -> High, bug | P13: =raw!P38 -> 0 | Q13: =raw!Q38 -> Fixed | R13: {=_xlfn.LET(_xlpm.txt,LOWER(B13&" "&C13&" "&F13&" "&M13&" "&O13),_xlfn.IFS(OR(IFERROR(SEARCH("diw",_xlpm.txt),0)>0,IFERROR(SEARCH("cost review",_xlpm.txt),0)>0,IFERROR(SEARCH("re-induction",_xlpm.txt),0)>0,IFERROR(SEARCH("second induction",_xlpm.txt),0)>0,IFERROR(SEARCH("quotation",_xlpm.txt),0)>0),"DIW/Cost Review",OR(IFERROR(SEARCH("swap",_xlpm.txt),0)>0,IFERROR(SEARCH("off-module",_xlpm.txt),0)>0,IFERROR(SEARCH("off module",_xlpm.txt),0)>0,IFERROR(SEARCH("dispatch module",_xlpm.txt),0)>0),"Swap Module",OR(IFERROR(SEARCH("notif",_xlpm.txt),0)>0,IFERROR(SEARCH("line manager",_xlpm.txt),0)>0,IFERROR(SEARCH("reject reason",_xlpm.txt),0)>0,IFERROR(SEARCH("approval",_xlpm.txt),0)>0,IFERROR(SEARCH("approve",_xlpm.txt),0)>0),"Notification",IFERROR(SEARCH("calendar",_xlpm.txt),0)>0,"Task Owner View",OR(IFERROR(SEARCH("task owner",_xlpm.txt),0)>0,IFERROR(SEARCH("pcd",_xlpm.txt),0)>0,IFERROR(SEARCH("acd",_xlpm.txt),0)>0,IFERROR(SEARCH("actual completion",_xlpm.txt),0)>0,IFERROR(SEARCH("delay",_xlpm.txt),0)>0,IFERROR(SEARCH("task ",_xlpm.txt),0)>0,IFERROR(SEARCH("tasks",_xlpm.txt),0)>0),"Task Owner Action",TRUE,"Other / General"))} -> Notification | S13: {=_xlfn.LET(_xlpm.txt,LOWER(B13&" "&C13&" "&F13&" "&M13&" "&O13),_xlfn.IFS(IFERROR(SEARCH("diw",_xlpm.txt),0)>0,"diw",IFERROR(SEARCH("cost review",_xlpm.txt),0)>0,"cost review",IFERROR(SEARCH("re-induction",_xlpm.txt),0)>0,"re-induction",IFERROR(SEARCH("second induction",_xlpm.txt),0)>0,"second induction",IFERROR(SEARCH("quotation",_xlpm.txt),0)>0,"quotation",IFERROR(SEARCH("swap",_xlpm.txt),0)>0,"swap",IFERROR(SEARCH("off-module",_xlpm.txt),0)>0,"off-module",IFERROR(SEARCH("off module",_xlpm.txt),0)>0,"off module",IFERROR(SEARCH("dispatch module",_xlpm.txt),0)>0,"dispatch module",IFERROR(SEARCH("notif",_xlpm.txt),0)>0,"notification",IFERROR(SEARCH("line manager",_xlpm.txt),0)>0,"line manager",IFERROR(SEARCH("reject reason",_xlpm.txt),0)>0,"reject reason",IFERROR(SEARCH("approval",_xlpm.txt),0)>0,"approval",IFERROR(SEARCH("approve",_xlpm.txt),0)>0,"approve",IFERROR(SEARCH("calendar",_xlpm.txt),0)>0,"calendar",IFERROR(SEARCH("task owner",_xlpm.txt),0)>0,"task owner",IFERROR(SEARCH("pcd",_xlpm.txt),0)>0,"PCD",IFERROR(SEARCH("acd",_xlpm.txt),0)>0,"ACD",IFERROR(SEARCH("actual completion",_xlpm.txt),0)>0,"actual completion",IFERROR(SEARCH("delay",_xlpm.txt),0)>0,"delay",IFERROR(SEARCH("task ",_xlpm.txt),0)>0,"task",IFERROR(SEARCH("tasks",_xlpm.txt),0)>0,"tasks",TRUE,"(no match)"))} -> approval | T13: High
A14: =raw!A94 -> 64 | B14: =raw!B94 -> Notification | C14: =raw!C94 -> System | D14: =raw!D94 -> Must | E14: =raw!E94 -> Bug | F14: =raw!F94 -> When there are no pending approval tasks, the approval notification icon displays system update logs. We expect the system to display nothing when there are no approval items for Approval Icon. | G14: =raw!G94 -> 46108 | H14: =raw!H94 -> Ray | ... Q14: =raw!Q94 -> Fixed | R14: {=_xlfn.LET(_xlpm.txt,LOWER(B14&" "&C14&" "&F14&" "&M14&" "&O14),_xlfn.IFS(OR(IFERROR(SEARCH("diw",_xlpm.txt),0)>0,IFERROR(SEARCH("cost review",_xlpm.txt),0)>0,IFERROR(SEARCH("re-induction",_xlpm.txt),0)>0,IFERROR(SEARCH("second induction",_xlpm.txt),0)>0,IFERROR(SEARCH("quotation",_xlpm.txt),0)>0),"DIW/Cost Review",OR(IFERROR(SEARCH("swap",_xlpm.txt),0)>0,IFERROR(SEARCH("off-module",_xlpm.txt),0)>0,IFERROR(SEARCH("off module",_xlpm.txt),0)>0,IFERROR(SEARCH("dispatch module",_xlpm.txt),0)>0),"Swap Module",OR(IFERROR(SEARCH("notif",_xlpm.txt),0)>0,IFERROR(SEARCH("line manager",_xlpm.txt),0)>0,IFERROR(SEARCH("reject reason",_xlpm.txt),0)>0,IFERROR(SEARCH("approval",_xlpm.txt),0)>0,IFERROR(SEARCH("approve",_xlpm.txt),0)>0),"Notification",IFERROR(SEARCH("calendar",_xlpm.txt),0)>0,"Task Owner View",OR(IFERROR(SEARCH("task owner",_xlpm.txt),0)>0,IFERROR(SEARCH("pcd",_xlpm.txt),0)>0,IFERROR(SEARCH("acd",_xlpm.txt),0)>0,IFERROR(SEARCH("actual completion",_xlpm.txt),0)>0,IFERROR(SEARCH("delay",_xlpm.txt),0)>0,IFERROR(SEARCH("task ",_xlpm.txt),0)>0,IFERROR(SEARCH("tasks",_xlpm.txt),0)>0),"Task Owner Action",TRUE,"Other / General"))} -> Notification | S14: {=_xlfn.LET(_xlpm.txt,LOWER(B14&" "&C14&" "&F14&" "&M14&" "&O14),_xlfn.IFS(IFERROR(SEARCH("diw",_xlpm.txt),0)>0,"diw",IFERROR(SEARCH("cost review",_xlpm.txt),0)>0,"cost review",IFERROR(SEARCH("re-induction",_xlpm.txt),0)>0,"re-induction",IFERROR(SEARCH("second induction",_xlpm.txt),0)>0,"second induction",IFERROR(SEARCH("quotation",_xlpm.txt),0)>0,"quotation",IFERROR(SEARCH("swap",_xlpm.txt),0)>0,"swap",IFERROR(SEARCH("off-module",_xlpm.txt),0)>0,"off-module",IFERROR(SEARCH("off module",_xlpm.txt),0)>0,"off module",IFERROR(SEARCH("dispatch module",_xlpm.txt),0)>0,"dispatch module",IFERROR(SEARCH("notif",_xlpm.txt),0)>0,"notification",IFERROR(SEARCH("line manager",_xlpm.txt),0)>0,"line manager",IFERROR(SEARCH("reject reason",_xlpm.txt),0)>0,"reject reason",IFERROR(SEARCH("approval",_xlpm.txt),0)>0,"approval",IFERROR(SEARCH("approve",_xlpm.txt),0)>0,"approve",IFERROR(SEARCH("calendar",_xlpm.txt),0)>0,"calendar",IFERROR(SEARCH("task owner",_xlpm.txt),0)>0,"task owner",IFERROR(SEARCH("pcd",_xlpm.txt),0)>0,"PCD",IFERROR(SEARCH("acd",_xlpm.txt),0)>0,"ACD",IFERROR(SEARCH("actual completion",_xlpm.txt),0)>0,"actual completion",IFERROR(SEARCH("delay",_xlpm.txt),0)>0,"delay",IFERROR(SEARCH("task ",_xlpm.txt),0)>0,"task",IFERROR(SEARCH("tasks",_xlpm.txt),0)>0,"tasks",TRUE,"(no match)"))} -> notification | T14: medium
A15: =raw!A102 -> 68 | B15: =raw!B102 -> Task Update | C15: =raw!C102 -> System | D15: =raw!D102 -> Must | E15: =raw!E102 -> Bug | F15: =raw!F102 -> what is the max length of reject reason? System error when the reason is a long text | G15: =raw!G102 -> 46113 | H15: =raw!H102 -> Ray | ... Q15: =raw!Q102 -> Not yet fix | R15: {=_xlfn.LET(_xlpm.txt,LOWER(B15&" "&C15&" "&F15&" "&M15&" "&O15),_xlfn.IFS(OR(IFERROR(SEARCH("diw",_xlpm.txt),0)>0,IFERROR(SEARCH("cost review",_xlpm.txt),0)>0,IFERROR(SEARCH("re-induction",_xlpm.txt),0)>0,IFERROR(SEARCH("second induction",_xlpm.txt),0)>0,IFERROR(SEARCH("quotation",_xlpm.txt),0)>0),"DIW/Cost Review",OR(IFERROR(SEARCH("swap",_xlpm.txt),0)>0,IFERROR(SEARCH("off-module",_xlpm.txt),0)>0,IFERROR(SEARCH("off module",_xlpm.txt),0)>0,IFERROR(SEARCH("dispatch module",_xlpm.txt),0)>0),"Swap Module",OR(IFERROR(SEARCH("notif",_xlpm.txt),0)>0,IFERROR(SEARCH("line manager",_xlpm.txt),0)>0,IFERROR(SEARCH("reject reason",_xlpm.txt),0)>0,IFERROR(SEARCH("approval",_xlpm.txt),0)>0,IFERROR(SEARCH("approve",_xlpm.txt),0)>0),"Notification",IFERROR(SEARCH("calendar",_xlpm.txt),0)>0,"Task Owner View",OR(IFERROR(SEARCH("task owner",_xlpm.txt),0)>0,IFERROR(SEARCH("pcd",_xlpm.txt),0)>0,IFERROR(SEARCH("acd",_xlpm.txt),0)>0,IFERROR(SEARCH("actual completion",_xlpm.txt),0)>0,IFERROR(SEARCH("delay",_xlpm.txt),0)>0,IFERROR(SEARCH("task ",_xlpm.txt),0)>0,IFERROR(SEARCH("tasks",_xlpm.txt),0)>0),"Task Owner Action",TRUE,"Other / General"))} -> Notification | S15: {=_xlfn.LET(_xlpm.txt,LOWER(B15&" "&C15&" "&F15&" "&M15&" "&O15),_xlfn.IFS(IFERROR(SEARCH("diw",_xlpm.txt),0)>0,"diw",IFERROR(SEARCH("cost review",_xlpm.txt),0)>0,"cost review",IFERROR(SEARCH("re-induction",_xlpm.txt),0)>0,"re-induction",IFERROR(SEARCH("second induction",_xlpm.txt),0)>0,"second induction",IFERROR(SEARCH("quotation",_xlpm.txt),0)>0,"quotation",IFERROR(SEARCH("swap",_xlpm.txt),0)>0,"swap",IFERROR(SEARCH("off-module",_xlpm.txt),0)>0,"off-module",IFERROR(SEARCH("off module",_xlpm.txt),0)>0,"off module",IFERROR(SEARCH("dispatch module",_xlpm.txt),0)>0,"dispatch module",IFERROR(SEARCH("notif",_xlpm.txt),0)>0,"notification",IFERROR(SEARCH("line manager",_xlpm.txt),0)>0,"line manager",IFERROR(SEARCH("reject reason",_xlpm.txt),0)>0,"reject reason",IFERROR(SEARCH("approval",_xlpm.txt),0)>0,"approval",IFERROR(SEARCH("approve",_xlpm.txt),0)>0,"approve",IFERROR(SEARCH("calendar",_xlpm.txt),0)>0,"calendar",IFERROR(SEARCH("task owner",_xlpm.txt),0)>0,"task owner",IFERROR(SEARCH("pcd",_xlpm.txt),0)>0,"PCD",IFERROR(SEARCH("acd",_xlpm.txt),0)>0,"ACD",IFERROR(SEARCH("actual completion",_xlpm.txt),0)>0,"actual completion",IFERROR(SEARCH("delay",_xlpm.txt),0)>0,"delay",IFERROR(SEARCH("task ",_xlpm.txt),0)>0,"task",IFERROR(SEARCH("tasks",_xlpm.txt),0)>0,"tasks",TRUE,"(no match)"))} -> reject reason | T15: medium
A16: =raw!A103 -> 69 | B16: =raw!B103 -> Notification - Approval | C16: =raw!C103 -> System | D16: =raw!D103 -> Must | E16: =raw!E103 -> Bug | F16: =raw!F103 -> In the view all page, Line manager section. Expected Completion Date means Projected Completion Date? if yes, please update. And please add the column of "Actual Completion Date" in this table too. | G16: =raw!G103 -> 46113 | H16: =raw!H103 -> Ray | ... Q16: =raw!Q103 -> 0 | R16: {=_xlfn.LET(_xlpm.txt,LOWER(B16&" "&C16&" "&F16&" "&M16&" "&O16),_xlfn.IFS(OR(IFERROR(SEARCH("diw",_xlpm.txt),0)>0,IFERROR(SEARCH("cost review",_xlpm.txt),0)>0,IFERROR(SEARCH("re-induction",_xlpm.txt),0)>0,IFERROR(SEARCH("second induction",_xlpm.txt),0)>0,IFERROR(SEARCH("quotation",_xlpm.txt),0)>0),"DIW/Cost Review",OR(IFERROR(SEARCH("swap",_xlpm.txt),0)>0,IFERROR(SEARCH("off-module",_xlpm.txt),0)>0,IFERROR(SEARCH("off module",_xlpm.txt),0)>0,IFERROR(SEARCH("dispatch module",_xlpm.txt),0)>0),"Swap Module",OR(IFERROR(SEARCH("notif",_xlpm.txt),0)>0,IFERROR(SEARCH("line manager",_xlpm.txt),0)>0,IFERROR(SEARCH("reject reason",_xlpm.txt),0)>0,IFERROR(SEARCH("approval",_xlpm.txt),0)>0,IFERROR(SEARCH("approve",_xlpm.txt),0)>0),"Notification",IFERROR(SEARCH("calendar",_xlpm.txt),0)>0,"Task Owner View",OR(IFERROR(SEARCH("task owner",_xlpm.txt),0)>0,IFERROR(SEARCH("pcd",_xlpm.txt),0)>0,IFERROR(SEARCH("acd",_xlpm.txt),0)>0,IFERROR(SEARCH("actual completion",_xlpm.txt),0)>0,IFERROR(SEARCH("delay",_xlpm.txt),0)>0,IFERROR(SEARCH("task ",_xlpm.txt),0)>0,IFERROR(SEARCH("tasks",_xlpm.txt),0)>0),"Task Owner Action",TRUE,"Other / General"))} -> Notification | S16: {=_xlfn.LET(_xlpm.txt,LOWER(B16&" "&C16&" "&F16&" "&M16&" "&O16),_xlfn.IFS(IFERROR(SEARCH("diw",_xlpm.txt),0)>0,"diw",IFERROR(SEARCH("cost review",_xlpm.txt),0)>0,"cost review",IFERROR(SEARCH("re-induction",_xlpm.txt),0)>0,"re-induction",IFERROR(SEARCH("second induction",_xlpm.txt),0)>0,"second induction",IFERROR(SEARCH("quotation",_xlpm.txt),0)>0,"quotation",IFERROR(SEARCH("swap",_xlpm.txt),0)>0,"swap",IFERROR(SEARCH("off-module",_xlpm.txt),0)>0,"off-module",IFERROR(SEARCH("off module",_xlpm.txt),0)>0,"off module",IFERROR(SEARCH("dispatch module",_xlpm.txt),0)>0,"dispatch module",IFERROR(SEARCH("notif",_xlpm.txt),0)>0,"notification",IFERROR(SEARCH("line manager",_xlpm.txt),0)>0,"line manager",IFERROR(SEARCH("reject reason",_xlpm.txt),0)>0,"reject reason",IFERROR(SEARCH("approval",_xlpm.txt),0)>0,"approval",IFERROR(SEARCH("approve",_xlpm.txt),0)>0,"approve",IFERROR(SEARCH("calendar",_xlpm.txt),0)>0,"calendar",IFERROR(SEARCH("task owner",_xlpm.txt),0)>0,"task owner",IFERROR(SEARCH("pcd",_xlpm.txt),0)>0,"PCD",IFERROR(SEARCH("acd",_xlpm.txt),0)>0,"ACD",IFERROR(SEARCH("actual completion",_xlpm.txt),0)>0,"actual completion",IFERROR(SEARCH("delay",_xlpm.txt),0)>0,"delay",IFERROR(SEARCH("task ",_xlpm.txt),0)>0,"task",IFERROR(SEARCH("tasks",_xlpm.txt),0)>0,"tasks",TRUE,"(no match)"))} -> notification | T16: low
