Workbook

Sheet 26035
A1: Task_no | B1: Task_name | C1: task_owner | D1: finish_date | E1: project_complete_date | F1: actual_finish_date | G1: flag_func
A2: 1 | B2: TRC COST DIW | C2: Customer Services | D2: 46089 | E2: 46089
A3: 3 | B3: Input Check COST DIW | C3: Module Change | D3: 46094 | E3: 46094
A4: 4 | B4: Induction Induction COST DIW | C4: Planning and Business Support | D4: 46096 | E4: 46096 | F4: 46096 | G4: Induction
A5: 5 | B5: Engine Bulk Strip COST DIW | C5: Module Change | D5: 46103 | E5: 46103
A6: 6GATE 1 | B6: Components Sentencing COST DIW | C6: Module Change | D6: 46107 | E6: 46107
A7: 7 | B7: Components Receipt at Vendor COST DIW | C7: Logistics | D7: 46114 | E7: 46114
A8: 8GATE 1 | B8: Engine Inspection COST DIW | C8: Module Change | D8: 46109 | E8: 46109
A9: 9 | B9: Module Strip COST DIW | C9: Module Repair | D9: 46109 | E9: 46109
A10: 9-MODULE 31 | B10: MODULE 31 Module Strip | C10: Module Repair | D10: 46109 | E10: 46109
A11: 9-MODULE 32 | B11: MODULE 32 Module Strip | C11: Module Repair | D11: 46109 | E11: 46109
A12: 9-MODULE 33 | B12: MODULE 33 Module Strip | C12: Module Repair | D12: 46109 | E12: 46109
A13: 9-MODULE 41 | B13: MODULE 41 Module Strip | C13: Module Repair | D13: 46109 | E13: 46109
A14: 9-MODULE 51 | B14: MODULE 51 Module Strip | C14: Module Repair | D14: 46109 | E14: 46109
A15: 9-MODULE 52 | B15: MODULE 52 Module Strip | C15: Module Repair | D15: 46109 | E15: 46109
A16: 10GATE 1 | B16: Critical Inspection | C16: Module Repair | D16: 46108 | E16: 46108
A17: 13 | B17: Critical Parts Orders | C17: Material Management | D17: 46109 | E17: 46109
A18: 14 | B18: Overseas Receipt At Vendor | C18: Logistics | D18: 46115 | E18: 46115
A19: 15GATE 1 | B19: Inspection BLT COST DIW | C19: Bench | D19: 46108 | E19: 46108 | G19: BLT
A20: 15-MODULE 31 | B20: MODULE 31 Inspection | C20: Bench | D20: 46108 | E20: 46108
A21: 15-MODULE 32 | B21: MODULE 32 Inspection | C21: Bench | D21: 46108 | E21: 46108
A22: 15-MODULE 33 | B22: MODULE 33 Inspection | C22: Bench | D22: 46108 | E22: 46108
A23: 15-MODULE 41 | B23: MODULE 41 Inspection | C23: Bench | D23: 46108 | E23: 46108
A24: 15-MODULE 51 | B24: MODULE 51 Inspection | C24: Bench | D24: 46108 | E24: 46108
A25: 15-MODULE 52 | B25: MODULE 52 Inspection | C25: Bench | D25: 46108 | E25: 46108
A26: 17 | B26: Instruct external parts supply | C26: Customer Services | D26: 46104 | E26: 46104
A27: 18 | B27: Inspection (XWB HPC) | C27: Bench | D27: 46113 | E27: 46113
A28: 19 | B28: Parts orders | C28: Material Management | D28: 46114 | E28: 46114
A29: 20 | B29: Rework Spare Clock Stop | C29: Material Management | D29: 46118 | E29: 46118
A30: 23 | B30: Customer Material Approval | C30: Customer Services | D30: 46124 | E30: 46124
A31: 27 | B31: Kitting Review | C31: Material Management | D31: 46137 | E31: 46137
A32: 28 | B32: Component Repair BFS | C32: Material Management | D32: 46145 | E32: 46145 | G32: BFS
A33: 29 | B33: Receive orders BFS | C33: Material Management | D33: 46145 | E33: 46145 | G33: BFS
A34: 30 | B34: Receive overseas repair - core engine parts BFS | C34: Material Management | D34: 46141 | E34: 46141 | G34: BFS
A35: 31 | B35: Core Module Parts Clock Stop | C35: Material Management | D35: 46143 | E35: 46143
A36: 32GATE 2 | B36: Core Modules Kitted BFS2 | C36: Material Management | D36: 46143 | E36: 46139 | G36: BFS2
A37: 32-MODULE 31 | B37: MODULE 31 Core Modules Kitted | C37: Material Management | D37: 46139 | E37: 46139
A38: 32-MODULE 32 | B38: MODULE 32 Core Modules Kitted | C38: Material Management | D38: 46139 | E38: 46139
A39: 32-MODULE 33 | B39: MODULE 33 Core Modules Kitted | C39: Material Management | D39: 46139 | E39: 46139
A40: 32-MODULE 41 | B40: MODULE 41 Core Modules Kitted | C40: Material Management | D40: 46139 | E40: 46139
...

Sheet 26035 (MST+26)
A1: Task_no | B1: Task_name | C1: task_owner | D1: finish_date | E1: project_complete_date | F1: actual_finish_date | G1: flag_func | H1: change_DF | I1: change_PCD | J1: change_ACD
A2: 1 | B2: TRC COST DIW | C2: Customer Services | D2: 46089 | E2: 46089 | H2: =D2-VLOOKUP(A2,'26035'!A:F,4,0) -> 0 | I2: =E2-VLOOKUP(A2,'26035'!A:F,5,0) -> 0 | J2: =F2-VLOOKUP(A2,'26035'!A:F,6,0) -> 0
A3: 3 | B3: Input Check COST DIW | C3: Module Change | D3: 46094 | E3: 46094 | H3: =D3-VLOOKUP(A3,'26035'!A:F,4,0) -> 0 | I3: =E3-VLOOKUP(A3,'26035'!A:F,5,0) -> 0 | J3: =F3-VLOOKUP(A3,'26035'!A:F,6,0) -> 0
A4: 4 | B4: Induction Induction COST DIW | C4: Planning and Business Support | D4: 46096 | E4: 46096 | F4: 46096 | G4: Induction | H4: =D4-VLOOKUP(A4,'26035'!A:F,4,0) -> 0 | I4: =E4-VLOOKUP(A4,'26035'!A:F,5,0) -> 0 | J4: =F4-VLOOKUP(A4,'26035'!A:F,6,0) -> 0
A5: 5 | B5: Engine Bulk Strip COST DIW | C5: Module Change | D5: 46103 | E5: 46103 | H5: =D5-VLOOKUP(A5,'26035'!A:F,4,0) -> 0 | I5: =E5-VLOOKUP(A5,'26035'!A:F,5,0) -> 0 | J5: =F5-VLOOKUP(A5,'26035'!A:F,6,0) -> 0
A6: 6GATE 1 | B6: Components Sentencing COST DIW | C6: Module Change | D6: 46107 | E6: 46107 | H6: =D6-VLOOKUP(A6,'26035'!A:F,4,0) -> 0 | I6: =E6-VLOOKUP(A6,'26035'!A:F,5,0) -> 0 | J6: =F6-VLOOKUP(A6,'26035'!A:F,6,0) -> 0
A7: 7 | B7: Components Receipt at Vendor COST DIW | C7: Logistics | D7: 46114 | E7: 46114 | H7: =D7-VLOOKUP(A7,'26035'!A:F,4,0) -> 0 | I7: =E7-VLOOKUP(A7,'26035'!A:F,5,0) -> 0 | J7: =F7-VLOOKUP(A7,'26035'!A:F,6,0) -> 0
A8: 8GATE 1 | B8: Engine Inspection COST DIW | C8: Module Change | D8: 46109 | E8: 46109 | H8: =D8-VLOOKUP(A8,'26035'!A:F,4,0) -> 0 | I8: =E8-VLOOKUP(A8,'26035'!A:F,5,0) -> 0 | J8: =F8-VLOOKUP(A8,'26035'!A:F,6,0) -> 0
A9: 9 | B9: Module Strip COST DIW | C9: Module Repair | D9: 46109 | E9: 46109 | H9: =D9-VLOOKUP(A9,'26035'!A:F,4,0) -> 0 | I9: =E9-VLOOKUP(A9,'26035'!A:F,5,0) -> 0 | J9: =F9-VLOOKUP(A9,'26035'!A:F,6,0) -> 0
A10: 9-MODULE 31 | B10: MODULE 31 Module Strip | C10: Module Repair | D10: 46109 | E10: 46109 | H10: =D10-VLOOKUP(A10,'26035'!A:F,4,0) -> 0 | I10: =E10-VLOOKUP(A10,'26035'!A:F,5,0) -> 0 | J10: =F10-VLOOKUP(A10,'26035'!A:F,6,0) -> 0
A11: 9-MODULE 32 | B11: MODULE 32 Module Strip | C11: Module Repair | D11: 46109 | E11: 46109 | H11: =D11-VLOOKUP(A11,'26035'!A:F,4,0) -> 0 | I11: =E11-VLOOKUP(A11,'26035'!A:F,5,0) -> 0 | J11: =F11-VLOOKUP(A11,'26035'!A:F,6,0) -> 0
A12: 9-MODULE 33 | B12: MODULE 33 Module Strip | C12: Module Repair | D12: 46109 | E12: 46109 | H12: =D12-VLOOKUP(A12,'26035'!A:F,4,0) -> 0 | I12: =E12-VLOOKUP(A12,'26035'!A:F,5,0) -> 0 | J12: =F12-VLOOKUP(A12,'26035'!A:F,6,0) -> 0
A13: 9-MODULE 41 | B13: MODULE 41 Module Strip | C13: Module Repair | D13: 46109 | E13: 46109 | H13: =D13-VLOOKUP(A13,'26035'!A:F,4,0) -> 0 | I13: =E13-VLOOKUP(A13,'26035'!A:F,5,0) -> 0 | J13: =F13-VLOOKUP(A13,'26035'!A:F,6,0) -> 0
A14: 9-MODULE 51 | B14: MODULE 51 Module Strip | C14: Module Repair | D14: 46109 | E14: 46109 | H14: =D14-VLOOKUP(A14,'26035'!A:F,4,0) -> 0 | I14: =E14-VLOOKUP(A14,'26035'!A:F,5,0) -> 0 | J14: =F14-VLOOKUP(A14,'26035'!A:F,6,0) -> 0
A15: 9-MODULE 52 | B15: MODULE 52 Module Strip | C15: Module Repair | D15: 46109 | E15: 46109 | H15: =D15-VLOOKUP(A15,'26035'!A:F,4,0) -> 0 | I15: =E15-VLOOKUP(A15,'26035'!A:F,5,0) -> 0 | J15: =F15-VLOOKUP(A15,'26035'!A:F,6,0) -> 0
A16: 10GATE 1 | B16: Critical Inspection | C16: Module Repair | D16: 46108 | E16: 46108 | H16: =D16-VLOOKUP(A16,'26035'!A:F,4,0) -> 0 | I16: =E16-VLOOKUP(A16,'26035'!A:F,5,0) -> 0 | J16: =F16-VLOOKUP(A16,'26035'!A:F,6,0) -> 0
A17: 13 | B17: Critical Parts Orders | C17: Material Management | D17: 46109 | E17: 46109 | H17: =D17-VLOOKUP(A17,'26035'!A:F,4,0) -> 0 | I17: =E17-VLOOKUP(A17,'26035'!A:F,5,0) -> 0 | J17: =F17-VLOOKUP(A17,'26035'!A:F,6,0) -> 0
A18: 14 | B18: Overseas Receipt At Vendor | C18: Logistics | D18: 46115 | E18: 46115 | H18: =D18-VLOOKUP(A18,'26035'!A:F,4,0) -> 0 | I18: =E18-VLOOKUP(A18,'26035'!A:F,5,0) -> 0 | J18: =F18-VLOOKUP(A18,'26035'!A:F,6,0) -> 0
A19: 15GATE 1 | B19: Inspection BLT COST DIW | C19: Bench | D19: 46108 | E19: 46108 | G19: BLT | H19: =D19-VLOOKUP(A19,'26035'!A:F,4,0) -> 0 | I19: =E19-VLOOKUP(A19,'26035'!A:F,5,0) -> 0 | J19: =F19-VLOOKUP(A19,'26035'!A:F,6,0) -> 0
A20: 15-MODULE 31 | B20: MODULE 31 Inspection | C20: Bench | D20: 46108 | E20: 46108 | H20: =D20-VLOOKUP(A20,'26035'!A:F,4,0) -> 0 | I20: =E20-VLOOKUP(A20,'26035'!A:F,5,0) -> 0 | J20: =F20-VLOOKUP(A20,'26035'!A:F,6,0) -> 0
A21: 15-MODULE 32 | B21: MODULE 32 Inspection | C21: Bench | D21: 46108 | E21: 46108 | H21: =D21-VLOOKUP(A21,'26035'!A:F,4,0) -> 0 | I21: =E21-VLOOKUP(A21,'26035'!A:F,5,0) -> 0 | J21: =F21-VLOOKUP(A21,'26035'!A:F,6,0) -> 0
A22: 15-MODULE 33 | B22: MODULE 33 Inspection | C22: Bench | D22: 46108 | E22: 46108 | H22: =D22-VLOOKUP(A22,'26035'!A:F,4,0) -> 0 | I22: =E22-VLOOKUP(A22,'26035'!A:F,5,0) -> 0 | J22: =F22-VLOOKUP(A22,'26035'!A:F,6,0) -> 0
A23: 15-MODULE 41 | B23: MODULE 41 Inspection | C23: Bench | D23: 46108 | E23: 46108 | H23: =D23-VLOOKUP(A23,'26035'!A:F,4,0) -> 0 | I23: =E23-VLOOKUP(A23,'26035'!A:F,5,0) -> 0 | J23: =F23-VLOOKUP(A23,'26035'!A:F,6,0) -> 0
A24: 15-MODULE 51 | B24: MODULE 51 Inspection | C24: Bench | D24: 46108 | E24: 46108 | H24: =D24-VLOOKUP(A24,'26035'!A:F,4,0) -> 0 | I24: =E24-VLOOKUP(A24,'26035'!A:F,5,0) -> 0 | J24: =F24-VLOOKUP(A24,'26035'!A:F,6,0) -> 0
A25: 15-MODULE 52 | B25: MODULE 52 Inspection | C25: Bench | D25: 46108 | E25: 46108 | H25: =D25-VLOOKUP(A25,'26035'!A:F,4,0) -> 0 | I25: =E25-VLOOKUP(A25,'26035'!A:F,5,0) -> 0 | J25: =F25-VLOOKUP(A25,'26035'!A:F,6,0) -> 0
A26: 17 | B26: Instruct external parts supply | C26: Customer Services | D26: 46104 | E26: 46104 | H26: =D26-VLOOKUP(A26,'26035'!A:F,4,0) -> 0 | I26: =E26-VLOOKUP(A26,'26035'!A:F,5,0) -> 0 | J26: =F26-VLOOKUP(A26,'26035'!A:F,6,0) -> 0
A27: 18 | B27: Inspection (XWB HPC) | C27: Bench | D27: 46113 | E27: 46113 | H27: =D27-VLOOKUP(A27,'26035'!A:F,4,0) -> 0 | I27: =E27-VLOOKUP(A27,'26035'!A:F,5,0) -> 0 | J27: =F27-VLOOKUP(A27,'26035'!A:F,6,0) -> 0
A28: 19 | B28: Parts orders | C28: Material Management | D28: 46114 | E28: 46114 | H28: =D28-VLOOKUP(A28,'26035'!A:F,4,0) -> 0 | I28: =E28-VLOOKUP(A28,'26035'!A:F,5,0) -> 0 | J28: =F28-VLOOKUP(A28,'26035'!A:F,6,0) -> 0
A29: 20 | B29: Rework Spare Clock Stop | C29: Material Management | D29: 46118 | E29: 46118 | H29: =D29-VLOOKUP(A29,'26035'!A:F,4,0) -> 0 | I29: =E29-VLOOKUP(A29,'26035'!A:F,5,0) -> 0 | J29: =F29-VLOOKUP(A29,'26035'!A:F,6,0) -> 0
A30: 23 | B30: Customer Material Approval | C30: Customer Services | D30: 46124 | E30: 46124 | H30: =D30-VLOOKUP(A30,'26035'!A:F,4,0) -> 0 | I30: =E30-VLOOKUP(A30,'26035'!A:F,5,0) -> 0 | J30: =F30-VLOOKUP(A30,'26035'!A:F,6,0) -> 0
A31: 27 | B31: Kitting Review | C31: Material Management | D31: 46137 | E31: 46137 | H31: =D31-VLOOKUP(A31,'26035'!A:F,4,0) -> 0 | I31: =E31-VLOOKUP(A31,'26035'!A:F,5,0) -> 0 | J31: =F31-VLOOKUP(A31,'26035'!A:F,6,0) -> 0
A32: 28 | B32: Component Repair BFS | C32: Material Management | D32: 46145 | E32: 46145 | G32: BFS | H32: =D32-VLOOKUP(A32,'26035'!A:F,4,0) -> 0 | I32: =E32-VLOOKUP(A32,'26035'!A:F,5,0) -> 0 | J32: =F32-VLOOKUP(A32,'26035'!A:F,6,0) -> 0
A33: 29 | B33: Receive orders BFS | C33: Material Management | D33: 46145 | E33: 46145 | G33: BFS | H33: =D33-VLOOKUP(A33,'26035'!A:F,4,0) -> 0 | I33: =E33-VLOOKUP(A33,'26035'!A:F,5,0) -> 0 | J33: =F33-VLOOKUP(A33,'26035'!A:F,6,0) -> 0
A34: 30 | B34: Receive overseas repair - core engine parts BFS | C34: Material Management | D34: 46141 | E34: 46141 | G34: BFS | H34: =D34-VLOOKUP(A34,'26035'!A:F,4,0) -> 0 | I34: =E34-VLOOKUP(A34,'26035'!A:F,5,0) -> 0 | J34: =F34-VLOOKUP(A34,'26035'!A:F,6,0) -> 0
A35: 31 | B35: Core Module Parts Clock Stop | C35: Material Management | D35: 46143 | E35: 46143 | H35: =D35-VLOOKUP(A35,'26035'!A:F,4,0) -> 0 | I35: =E35-VLOOKUP(A35,'26035'!A:F,5,0) -> 0 | J35: =F35-VLOOKUP(A35,'26035'!A:F,6,0) -> 0
A36: 32GATE 2 | B36: Core Modules Kitted BFS2 | C36: Material Management | D36: 46143 | E36: 46165 | G36: BFS2 | H36: =D36-VLOOKUP(A36,'26035'!A:F,4,0) -> 0 | I36: =E36-VLOOKUP(A36,'26035'!A:F,5,0) -> 26 | J36: =F36-VLOOKUP(A36,'26035'!A:F,6,0) -> 0
A37: 32-MODULE 31 | B37: MODULE 31 Core Modules Kitted | C37: Material Management | D37: 46139 | E37: 46165 | H37: =D37-VLOOKUP(A37,'26035'!A:F,4,0) -> 0 | I37: =E37-VLOOKUP(A37,'26035'!A:F,5,0) -> 26 | J37: =F37-VLOOKUP(A37,'26035'!A:F,6,0) -> 0
A38: 32-MODULE 32 | B38: MODULE 32 Core Modules Kitted | C38: Material Management | D38: 46139 | E38: 46165 | H38: =D38-VLOOKUP(A38,'26035'!A:F,4,0) -> 0 | I38: =E38-VLOOKUP(A38,'26035'!A:F,5,0) -> 26 | J38: =F38-VLOOKUP(A38,'26035'!A:F,6,0) -> 0
A39: 32-MODULE 33 | B39: MODULE 33 Core Modules Kitted | C39: Material Management | D39: 46139 | E39: 46165 | H39: =D39-VLOOKUP(A39,'26035'!A:F,4,0) -> 0 | I39: =E39-VLOOKUP(A39,'26035'!A:F,5,0) -> 26 | J39: =F39-VLOOKUP(A39,'26035'!A:F,6,0) -> 0
A40: 32-MODULE 41 | B40: MODULE 41 Core Modules Kitted | C40: Material Management | D40: 46139 | E40: 46165 | H40: =D40-VLOOKUP(A40,'26035'!A:F,4,0) -> 0 | I40: =E40-VLOOKUP(A40,'26035'!A:F,5,0) -> 26 | J40: =F40-VLOOKUP(A40,'26035'!A:F,6,0) -> 0
...

Sheet 26035 (MST-26)
A1: Task_no | B1: Task_name | C1: task_owner | D1: finish_date | E1: project_complete_date | F1: actual_finish_date | G1: flag_func | H1: change_DF | I1: change_PCD | J1: change_ACD
A2: 1 | B2: TRC COST DIW | C2: Customer Services | D2: 46089 | E2: 46089 | H2: =D2-VLOOKUP(A2,'26035'!A:F,4,0) -> 0 | I2: =E2-VLOOKUP(A2,'26035'!A:F,5,0) -> 0 | J2: =F2-VLOOKUP(A2,'26035'!A:F,6,0) -> 0
A3: 3 | B3: Input Check COST DIW | C3: Module Change | D3: 46094 | E3: 46094 | H3: =D3-VLOOKUP(A3,'26035'!A:F,4,0) -> 0 | I3: =E3-VLOOKUP(A3,'26035'!A:F,5,0) -> 0 | J3: =F3-VLOOKUP(A3,'26035'!A:F,6,0) -> 0
A4: 4 | B4: Induction Induction COST DIW | C4: Planning and Business Support | D4: 46096 | E4: 46096 | F4: 46096 | G4: Induction | H4: =D4-VLOOKUP(A4,'26035'!A:F,4,0) -> 0 | I4: =E4-VLOOKUP(A4,'26035'!A:F,5,0) -> 0 | J4: =F4-VLOOKUP(A4,'26035'!A:F,6,0) -> 0
A5: 5 | B5: Engine Bulk Strip COST DIW | C5: Module Change | D5: 46103 | E5: 46103 | H5: =D5-VLOOKUP(A5,'26035'!A:F,4,0) -> 0 | I5: =E5-VLOOKUP(A5,'26035'!A:F,5,0) -> 0 | J5: =F5-VLOOKUP(A5,'26035'!A:F,6,0) -> 0
A6: 6GATE 1 | B6: Components Sentencing COST DIW | C6: Module Change | D6: 46107 | E6: 46107 | H6: =D6-VLOOKUP(A6,'26035'!A:F,4,0) -> 0 | I6: =E6-VLOOKUP(A6,'26035'!A:F,5,0) -> 0 | J6: =F6-VLOOKUP(A6,'26035'!A:F,6,0) -> 0
A7: 7 | B7: Components Receipt at Vendor COST DIW | C7: Logistics | D7: 46114 | E7: 46114 | H7: =D7-VLOOKUP(A7,'26035'!A:F,4,0) -> 0 | I7: =E7-VLOOKUP(A7,'26035'!A:F,5,0) -> 0 | J7: =F7-VLOOKUP(A7,'26035'!A:F,6,0) -> 0
A8: 8GATE 1 | B8: Engine Inspection COST DIW | C8: Module Change | D8: 46109 | E8: 46109 | H8: =D8-VLOOKUP(A8,'26035'!A:F,4,0) -> 0 | I8: =E8-VLOOKUP(A8,'26035'!A:F,5,0) -> 0 | J8: =F8-VLOOKUP(A8,'26035'!A:F,6,0) -> 0
A9: 9 | B9: Module Strip COST DIW | C9: Module Repair | D9: 46109 | E9: 46109 | H9: =D9-VLOOKUP(A9,'26035'!A:F,4,0) -> 0 | I9: =E9-VLOOKUP(A9,'26035'!A:F,5,0) -> 0 | J9: =F9-VLOOKUP(A9,'26035'!A:F,6,0) -> 0
A10: 9-MODULE 31 | B10: MODULE 31 Module Strip | C10: Module Repair | D10: 46109 | E10: 46109 | H10: =D10-VLOOKUP(A10,'26035'!A:F,4,0) -> 0 | I10: =E10-VLOOKUP(A10,'26035'!A:F,5,0) -> 0 | J10: =F10-VLOOKUP(A10,'26035'!A:F,6,0) -> 0
A11: 9-MODULE 32 | B11: MODULE 32 Module Strip | C11: Module Repair | D11: 46109 | E11: 46109 | H11: =D11-VLOOKUP(A11,'26035'!A:F,4,0) -> 0 | I11: =E11-VLOOKUP(A11,'26035'!A:F,5,0) -> 0 | J11: =F11-VLOOKUP(A11,'26035'!A:F,6,0) -> 0
A12: 9-MODULE 33 | B12: MODULE 33 Module Strip | C12: Module Repair | D12: 46109 | E12: 46109 | H12: =D12-VLOOKUP(A12,'26035'!A:F,4,0) -> 0 | I12: =E12-VLOOKUP(A12,'26035'!A:F,5,0) -> 0 | J12: =F12-VLOOKUP(A12,'26035'!A:F,6,0) -> 0
A13: 9-MODULE 41 | B13: MODULE 41 Module Strip | C13: Module Repair | D13: 46109 | E13: 46109 | H13: =D13-VLOOKUP(A13,'26035'!A:F,4,0) -> 0 | I13: =E13-VLOOKUP(A13,'26035'!A:F,5,0) -> 0 | J13: =F13-VLOOKUP(A13,'26035'!A:F,6,0) -> 0
A14: 9-MODULE 51 | B14: MODULE 51 Module Strip | C14: Module Repair | D14: 46109 | E14: 46109 | H14: =D14-VLOOKUP(A14,'26035'!A:F,4,0) -> 0 | I14: =E14-VLOOKUP(A14,'26035'!A:F,5,0) -> 0 | J14: =F14-VLOOKUP(A14,'26035'!A:F,6,0) -> 0
A15: 9-MODULE 52 | B15: MODULE 52 Module Strip | C15: Module Repair | D15: 46109 | E15: 46109 | H15: =D15-VLOOKUP(A15,'26035'!A:F,4,0) -> 0 | I15: =E15-VLOOKUP(A15,'26035'!A:F,5,0) -> 0 | J15: =F15-VLOOKUP(A15,'26035'!A:F,6,0) -> 0
A16: 10GATE 1 | B16: Critical Inspection | C16: Module Repair | D16: 46108 | E16: 46108 | H16: =D16-VLOOKUP(A16,'26035'!A:F,4,0) -> 0 | I16: =E16-VLOOKUP(A16,'26035'!A:F,5,0) -> 0 | J16: =F16-VLOOKUP(A16,'26035'!A:F,6,0) -> 0
A17: 13 | B17: Critical Parts Orders | C17: Material Management | D17: 46109 | E17: 46109 | H17: =D17-VLOOKUP(A17,'26035'!A:F,4,0) -> 0 | I17: =E17-VLOOKUP(A17,'26035'!A:F,5,0) -> 0 | J17: =F17-VLOOKUP(A17,'26035'!A:F,6,0) -> 0
A18: 14 | B18: Overseas Receipt At Vendor | C18: Logistics | D18: 46115 | E18: 46115 | H18: =D18-VLOOKUP(A18,'26035'!A:F,4,0) -> 0 | I18: =E18-VLOOKUP(A18,'26035'!A:F,5,0) -> 0 | J18: =F18-VLOOKUP(A18,'26035'!A:F,6,0) -> 0
A19: 15GATE 1 | B19: Inspection BLT COST DIW | C19: Bench | D19: 46108 | E19: 46108 | G19: BLT | H19: =D19-VLOOKUP(A19,'26035'!A:F,4,0) -> 0 | I19: =E19-VLOOKUP(A19,'26035'!A:F,5,0) -> 0 | J19: =F19-VLOOKUP(A19,'26035'!A:F,6,0) -> 0
A20: 15-MODULE 31 | B20: MODULE 31 Inspection | C20: Bench | D20: 46108 | E20: 46108 | H20: =D20-VLOOKUP(A20,'26035'!A:F,4,0) -> 0 | I20: =E20-VLOOKUP(A20,'26035'!A:F,5,0) -> 0 | J20: =F20-VLOOKUP(A20,'26035'!A:F,6,0) -> 0
A21: 15-MODULE 32 | B21: MODULE 32 Inspection | C21: Bench | D21: 46108 | E21: 46108 | H21: =D21-VLOOKUP(A21,'26035'!A:F,4,0) -> 0 | I21: =E21-VLOOKUP(A21,'26035'!A:F,5,0) -> 0 | J21: =F21-VLOOKUP(A21,'26035'!A:F,6,0) -> 0
A22: 15-MODULE 33 | B22: MODULE 33 Inspection | C22: Bench | D22: 46108 | E22: 46108 | H22: =D22-VLOOKUP(A22,'26035'!A:F,4,0) -> 0 | I22: =E22-VLOOKUP(A22,'26035'!A:F,5,0) -> 0 | J22: =F22-VLOOKUP(A22,'26035'!A:F,6,0) -> 0
A23: 15-MODULE 41 | B23: MODULE 41 Inspection | C23: Bench | D23: 46108 | E23: 46108 | H23: =D23-VLOOKUP(A23,'26035'!A:F,4,0) -> 0 | I23: =E23-VLOOKUP(A23,'26035'!A:F,5,0) -> 0 | J23: =F23-VLOOKUP(A23,'26035'!A:F,6,0) -> 0
A24: 15-MODULE 51 | B24: MODULE 51 Inspection | C24: Bench | D24: 46108 | E24: 46108 | H24: =D24-VLOOKUP(A24,'26035'!A:F,4,0) -> 0 | I24: =E24-VLOOKUP(A24,'26035'!A:F,5,0) -> 0 | J24: =F24-VLOOKUP(A24,'26035'!A:F,6,0) -> 0
A25: 15-MODULE 52 | B25: MODULE 52 Inspection | C25: Bench | D25: 46108 | E25: 46108 | H25: =D25-VLOOKUP(A25,'26035'!A:F,4,0) -> 0 | I25: =E25-VLOOKUP(A25,'26035'!A:F,5,0) -> 0 | J25: =F25-VLOOKUP(A25,'26035'!A:F,6,0) -> 0
A26: 17 | B26: Instruct external parts supply | C26: Customer Services | D26: 46104 | E26: 46104 | H26: =D26-VLOOKUP(A26,'26035'!A:F,4,0) -> 0 | I26: =E26-VLOOKUP(A26,'26035'!A:F,5,0) -> 0 | J26: =F26-VLOOKUP(A26,'26035'!A:F,6,0) -> 0
A27: 18 | B27: Inspection (XWB HPC) | C27: Bench | D27: 46113 | E27: 46113 | H27: =D27-VLOOKUP(A27,'26035'!A:F,4,0) -> 0 | I27: =E27-VLOOKUP(A27,'26035'!A:F,5,0) -> 0 | J27: =F27-VLOOKUP(A27,'26035'!A:F,6,0) -> 0
A28: 19 | B28: Parts orders | C28: Material Management | D28: 46114 | E28: 46114 | H28: =D28-VLOOKUP(A28,'26035'!A:F,4,0) -> 0 | I28: =E28-VLOOKUP(A28,'26035'!A:F,5,0) -> 0 | J28: =F28-VLOOKUP(A28,'26035'!A:F,6,0) -> 0
A29: 20 | B29: Rework Spare Clock Stop | C29: Material Management | D29: 46118 | E29: 46118 | H29: =D29-VLOOKUP(A29,'26035'!A:F,4,0) -> 0 | I29: =E29-VLOOKUP(A29,'26035'!A:F,5,0) -> 0 | J29: =F29-VLOOKUP(A29,'26035'!A:F,6,0) -> 0
A30: 23 | B30: Customer Material Approval | C30: Customer Services | D30: 46124 | E30: 46124 | H30: =D30-VLOOKUP(A30,'26035'!A:F,4,0) -> 0 | I30: =E30-VLOOKUP(A30,'26035'!A:F,5,0) -> 0 | J30: =F30-VLOOKUP(A30,'26035'!A:F,6,0) -> 0
A31: 27 | B31: Kitting Review | C31: Material Management | D31: 46137 | E31: 46137 | H31: =D31-VLOOKUP(A31,'26035'!A:F,4,0) -> 0 | I31: =E31-VLOOKUP(A31,'26035'!A:F,5,0) -> 0 | J31: =F31-VLOOKUP(A31,'26035'!A:F,6,0) -> 0
A32: 28 | B32: Component Repair BFS | C32: Material Management | D32: 46145 | E32: 46145 | G32: BFS | H32: =D32-VLOOKUP(A32,'26035'!A:F,4,0) -> 0 | I32: =E32-VLOOKUP(A32,'26035'!A:F,5,0) -> 0 | J32: =F32-VLOOKUP(A32,'26035'!A:F,6,0) -> 0
A33: 29 | B33: Receive orders BFS | C33: Material Management | D33: 46145 | E33: 46145 | G33: BFS | H33: =D33-VLOOKUP(A33,'26035'!A:F,4,0) -> 0 | I33: =E33-VLOOKUP(A33,'26035'!A:F,5,0) -> 0 | J33: =F33-VLOOKUP(A33,'26035'!A:F,6,0) -> 0
A34: 30 | B34: Receive overseas repair - core engine parts BFS | C34: Material Management | D34: 46141 | E34: 46141 | G34: BFS | H34: =D34-VLOOKUP(A34,'26035'!A:F,4,0) -> 0 | I34: =E34-VLOOKUP(A34,'26035'!A:F,5,0) -> 0 | J34: =F34-VLOOKUP(A34,'26035'!A:F,6,0) -> 0
A35: 31 | B35: Core Module Parts Clock Stop | C35: Material Management | D35: 46143 | E35: 46143 | H35: =D35-VLOOKUP(A35,'26035'!A:F,4,0) -> 0 | I35: =E35-VLOOKUP(A35,'26035'!A:F,5,0) -> 0 | J35: =F35-VLOOKUP(A35,'26035'!A:F,6,0) -> 0
A36: 32GATE 2 | B36: Core Modules Kitted BFS2 | C36: Material Management | D36: 46143 | E36: 46139 | G36: BFS2 | H36: =D36-VLOOKUP(A36,'26035'!A:F,4,0) -> 0 | I36: =E36-VLOOKUP(A36,'26035'!A:F,5,0) -> 0 | J36: =F36-VLOOKUP(A36,'26035'!A:F,6,0) -> 0
A37: 32-MODULE 31 | B37: MODULE 31 Core Modules Kitted | C37: Material Management | D37: 46139 | E37: 46139 | H37: =D37-VLOOKUP(A37,'26035'!A:F,4,0) -> 0 | I37: =E37-VLOOKUP(A37,'26035'!A:F,5,0) -> 0 | J37: =F37-VLOOKUP(A37,'26035'!A:F,6,0) -> 0
A38: 32-MODULE 32 | B38: MODULE 32 Core Modules Kitted | C38: Material Management | D38: 46139 | E38: 46139 | H38: =D38-VLOOKUP(A38,'26035'!A:F,4,0) -> 0 | I38: =E38-VLOOKUP(A38,'26035'!A:F,5,0) -> 0 | J38: =F38-VLOOKUP(A38,'26035'!A:F,6,0) -> 0
A39: 32-MODULE 33 | B39: MODULE 33 Core Modules Kitted | C39: Material Management | D39: 46139 | E39: 46139 | H39: =D39-VLOOKUP(A39,'26035'!A:F,4,0) -> 0 | I39: =E39-VLOOKUP(A39,'26035'!A:F,5,0) -> 0 | J39: =F39-VLOOKUP(A39,'26035'!A:F,6,0) -> 0
A40: 32-MODULE 41 | B40: MODULE 41 Core Modules Kitted | C40: Material Management | D40: 46139 | E40: 46139 | H40: =D40-VLOOKUP(A40,'26035'!A:F,4,0) -> 0 | I40: =E40-VLOOKUP(A40,'26035'!A:F,5,0) -> 0 | J40: =F40-VLOOKUP(A40,'26035'!A:F,6,0) -> 0
...

Sheet 26035 (MST-5)
A1: Task_no | B1: Task_name | C1: task_owner | D1: finish_date | E1: project_complete_date | F1: actual_finish_date | G1: flag_func | H1: change_DF | I1: change_PCD | J1: change_ACD
A2: 1 | B2: TRC COST DIW | C2: Customer Services | D2: 46089 | E2: 46089 | H2: =D2-VLOOKUP(A2,'26035'!A:F,4,0) -> 0 | I2: =E2-VLOOKUP(A2,'26035'!A:F,5,0) -> 0 | J2: =F2-VLOOKUP(A2,'26035'!A:F,6,0) -> 0
A3: 3 | B3: Input Check COST DIW | C3: Module Change | D3: 46094 | E3: 46094 | H3: =D3-VLOOKUP(A3,'26035'!A:F,4,0) -> 0 | I3: =E3-VLOOKUP(A3,'26035'!A:F,5,0) -> 0 | J3: =F3-VLOOKUP(A3,'26035'!A:F,6,0) -> 0
A4: 4 | B4: Induction Induction COST DIW | C4: Planning and Business Support | D4: 46096 | E4: 46096 | F4: 46096 | G4: Induction | H4: =D4-VLOOKUP(A4,'26035'!A:F,4,0) -> 0 | I4: =E4-VLOOKUP(A4,'26035'!A:F,5,0) -> 0 | J4: =F4-VLOOKUP(A4,'26035'!A:F,6,0) -> 0
A5: 5 | B5: Engine Bulk Strip COST DIW | C5: Module Change | D5: 46103 | E5: 46103 | H5: =D5-VLOOKUP(A5,'26035'!A:F,4,0) -> 0 | I5: =E5-VLOOKUP(A5,'26035'!A:F,5,0) -> 0 | J5: =F5-VLOOKUP(A5,'26035'!A:F,6,0) -> 0
A6: 6GATE 1 | B6: Components Sentencing COST DIW | C6: Module Change | D6: 46107 | E6: 46107 | H6: =D6-VLOOKUP(A6,'26035'!A:F,4,0) -> 0 | I6: =E6-VLOOKUP(A6,'26035'!A:F,5,0) -> 0 | J6: =F6-VLOOKUP(A6,'26035'!A:F,6,0) -> 0
A7: 7 | B7: Components Receipt at Vendor COST DIW | C7: Logistics | D7: 46114 | E7: 46114 | H7: =D7-VLOOKUP(A7,'26035'!A:F,4,0) -> 0 | I7: =E7-VLOOKUP(A7,'26035'!A:F,5,0) -> 0 | J7: =F7-VLOOKUP(A7,'26035'!A:F,6,0) -> 0
A8: 8GATE 1 | B8: Engine Inspection COST DIW | C8: Module Change | D8: 46109 | E8: 46109 | H8: =D8-VLOOKUP(A8,'26035'!A:F,4,0) -> 0 | I8: =E8-VLOOKUP(A8,'26035'!A:F,5,0) -> 0 | J8: =F8-VLOOKUP(A8,'26035'!A:F,6,0) -> 0
A9: 9 | B9: Module Strip COST DIW | C9: Module Repair | D9: 46109 | E9: 46109 | H9: =D9-VLOOKUP(A9,'26035'!A:F,4,0) -> 0 | I9: =E9-VLOOKUP(A9,'26035'!A:F,5,0) -> 0 | J9: =F9-VLOOKUP(A9,'26035'!A:F,6,0) -> 0
A10: 9-MODULE 31 | B10: MODULE 31 Module Strip | C10: Module Repair | D10: 46109 | E10: 46109 | H10: =D10-VLOOKUP(A10,'26035'!A:F,4,0) -> 0 | I10: =E10-VLOOKUP(A10,'26035'!A:F,5,0) -> 0 | J10: =F10-VLOOKUP(A10,'26035'!A:F,6,0) -> 0
A11: 9-MODULE 32 | B11: MODULE 32 Module Strip | C11: Module Repair | D11: 46109 | E11: 46109 | H11: =D11-VLOOKUP(A11,'26035'!A:F,4,0) -> 0 | I11: =E11-VLOOKUP(A11,'26035'!A:F,5,0) -> 0 | J11: =F11-VLOOKUP(A11,'26035'!A:F,6,0) -> 0
A12: 9-MODULE 33 | B12: MODULE 33 Module Strip | C12: Module Repair | D12: 46109 | E12: 46109 | H12: =D12-VLOOKUP(A12,'26035'!A:F,4,0) -> 0 | I12: =E12-VLOOKUP(A12,'26035'!A:F,5,0) -> 0 | J12: =F12-VLOOKUP(A12,'26035'!A:F,6,0) -> 0
A13: 9-MODULE 41 | B13: MODULE 41 Module Strip | C13: Module Repair | D13: 46109 | E13: 46109 | H13: =D13-VLOOKUP(A13,'26035'!A:F,4,0) -> 0 | I13: =E13-VLOOKUP(A13,'26035'!A:F,5,0) -> 0 | J13: =F13-VLOOKUP(A13,'26035'!A:F,6,0) -> 0
A14: 9-MODULE 51 | B14: MODULE 51 Module Strip | C14: Module Repair | D14: 46109 | E14: 46109 | H14: =D14-VLOOKUP(A14,'26035'!A:F,4,0) -> 0 | I14: =E14-VLOOKUP(A14,'26035'!A:F,5,0) -> 0 | J14: =F14-VLOOKUP(A14,'26035'!A:F,6,0) -> 0
A15: 9-MODULE 52 | B15: MODULE 52 Module Strip | C15: Module Repair | D15: 46109 | E15: 46109 | H15: =D15-VLOOKUP(A15,'26035'!A:F,4,0) -> 0 | I15: =E15-VLOOKUP(A15,'26035'!A:F,5,0) -> 0 | J15: =F15-VLOOKUP(A15,'26035'!A:F,6,0) -> 0
A16: 10GATE 1 | B16: Critical Inspection | C16: Module Repair | D16: 46108 | E16: 46108 | H16: =D16-VLOOKUP(A16,'26035'!A:F,4,0) -> 0 | I16: =E16-VLOOKUP(A16,'26035'!A:F,5,0) -> 0 | J16: =F16-VLOOKUP(A16,'26035'!A:F,6,0) -> 0
A17: 13 | B17: Critical Parts Orders | C17: Material Management | D17: 46109 | E17: 46109 | H17: =D17-VLOOKUP(A17,'26035'!A:F,4,0) -> 0 | I17: =E17-VLOOKUP(A17,'26035'!A:F,5,0) -> 0 | J17: =F17-VLOOKUP(A17,'26035'!A:F,6,0) -> 0
A18: 14 | B18: Overseas Receipt At Vendor | C18: Logistics | D18: 46115 | E18: 46115 | H18: =D18-VLOOKUP(A18,'26035'!A:F,4,0) -> 0 | I18: =E18-VLOOKUP(A18,'26035'!A:F,5,0) -> 0 | J18: =F18-VLOOKUP(A18,'26035'!A:F,6,0) -> 0
A19: 15GATE 1 | B19: Inspection BLT COST DIW | C19: Bench | D19: 46108 | E19: 46108 | G19: BLT | H19: =D19-VLOOKUP(A19,'26035'!A:F,4,0) -> 0 | I19: =E19-VLOOKUP(A19,'26035'!A:F,5,0) -> 0 | J19: =F19-VLOOKUP(A19,'26035'!A:F,6,0) -> 0
A20: 15-MODULE 31 | B20: MODULE 31 Inspection | C20: Bench | D20: 46108 | E20: 46108 | H20: =D20-VLOOKUP(A20,'26035'!A:F,4,0) -> 0 | I20: =E20-VLOOKUP(A20,'26035'!A:F,5,0) -> 0 | J20: =F20-VLOOKUP(A20,'26035'!A:F,6,0) -> 0
A21: 15-MODULE 32 | B21: MODULE 32 Inspection | C21: Bench | D21: 46108 | E21: 46108 | H21: =D21-VLOOKUP(A21,'26035'!A:F,4,0) -> 0 | I21: =E21-VLOOKUP(A21,'26035'!A:F,5,0) -> 0 | J21: =F21-VLOOKUP(A21,'26035'!A:F,6,0) -> 0
A22: 15-MODULE 33 | B22: MODULE 33 Inspection | C22: Bench | D22: 46108 | E22: 46108 | H22: =D22-VLOOKUP(A22,'26035'!A:F,4,0) -> 0 | I22: =E22-VLOOKUP(A22,'26035'!A:F,5,0) -> 0 | J22: =F22-VLOOKUP(A22,'26035'!A:F,6,0) -> 0
A23: 15-MODULE 41 | B23: MODULE 41 Inspection | C23: Bench | D23: 46108 | E23: 46108 | H23: =D23-VLOOKUP(A23,'26035'!A:F,4,0) -> 0 | I23: =E23-VLOOKUP(A23,'26035'!A:F,5,0) -> 0 | J23: =F23-VLOOKUP(A23,'26035'!A:F,6,0) -> 0
A24: 15-MODULE 51 | B24: MODULE 51 Inspection | C24: Bench | D24: 46108 | E24: 46108 | H24: =D24-VLOOKUP(A24,'26035'!A:F,4,0) -> 0 | I24: =E24-VLOOKUP(A24,'26035'!A:F,5,0) -> 0 | J24: =F24-VLOOKUP(A24,'26035'!A:F,6,0) -> 0
A25: 15-MODULE 52 | B25: MODULE 52 Inspection | C25: Bench | D25: 46108 | E25: 46108 | H25: =D25-VLOOKUP(A25,'26035'!A:F,4,0) -> 0 | I25: =E25-VLOOKUP(A25,'26035'!A:F,5,0) -> 0 | J25: =F25-VLOOKUP(A25,'26035'!A:F,6,0) -> 0
A26: 17 | B26: Instruct external parts supply | C26: Customer Services | D26: 46104 | E26: 46104 | H26: =D26-VLOOKUP(A26,'26035'!A:F,4,0) -> 0 | I26: =E26-VLOOKUP(A26,'26035'!A:F,5,0) -> 0 | J26: =F26-VLOOKUP(A26,'26035'!A:F,6,0) -> 0
A27: 18 | B27: Inspection (XWB HPC) | C27: Bench | D27: 46113 | E27: 46113 | H27: =D27-VLOOKUP(A27,'26035'!A:F,4,0) -> 0 | I27: =E27-VLOOKUP(A27,'26035'!A:F,5,0) -> 0 | J27: =F27-VLOOKUP(A27,'26035'!A:F,6,0) -> 0
A28: 19 | B28: Parts orders | C28: Material Management | D28: 46114 | E28: 46114 | H28: =D28-VLOOKUP(A28,'26035'!A:F,4,0) -> 0 | I28: =E28-VLOOKUP(A28,'26035'!A:F,5,0) -> 0 | J28: =F28-VLOOKUP(A28,'26035'!A:F,6,0) -> 0
A29: 20 | B29: Rework Spare Clock Stop | C29: Material Management | D29: 46118 | E29: 46118 | H29: =D29-VLOOKUP(A29,'26035'!A:F,4,0) -> 0 | I29: =E29-VLOOKUP(A29,'26035'!A:F,5,0) -> 0 | J29: =F29-VLOOKUP(A29,'26035'!A:F,6,0) -> 0
A30: 23 | B30: Customer Material Approval | C30: Customer Services | D30: 46124 | E30: 46124 | H30: =D30-VLOOKUP(A30,'26035'!A:F,4,0) -> 0 | I30: =E30-VLOOKUP(A30,'26035'!A:F,5,0) -> 0 | J30: =F30-VLOOKUP(A30,'26035'!A:F,6,0) -> 0
A31: 27 | B31: Kitting Review | C31: Material Management | D31: 46137 | E31: 46137 | H31: =D31-VLOOKUP(A31,'26035'!A:F,4,0) -> 0 | I31: =E31-VLOOKUP(A31,'26035'!A:F,5,0) -> 0 | J31: =F31-VLOOKUP(A31,'26035'!A:F,6,0) -> 0
A32: 28 | B32: Component Repair BFS | C32: Material Management | D32: 46145 | E32: 46145 | F32: 46127 | G32: BFS | H32: =D32-VLOOKUP(A32,'26035'!A:F,4,0) -> 0 | I32: =E32-VLOOKUP(A32,'26035'!A:F,5,0) -> 0 | J32: =F32-VLOOKUP(A32,'26035'!A:F,6,0) -> 46127 | K32: <- no change if ACD is filled
A33: 29 | B33: Receive orders BFS | C33: Material Management | D33: 46145 | E33: 46140 | G33: BFS | H33: =D33-VLOOKUP(A33,'26035'!A:F,4,0) -> 0 | I33: =E33-VLOOKUP(A33,'26035'!A:F,5,0) -> -5 | J33: =F33-VLOOKUP(A33,'26035'!A:F,6,0) -> 0 | K33: <- date change even the task disabled
A34: 30 | B34: Receive overseas repair - core engine parts BFS | C34: Material Management | D34: 46141 | E34: 46136 | G34: BFS | H34: =D34-VLOOKUP(A34,'26035'!A:F,4,0) -> 0 | I34: =E34-VLOOKUP(A34,'26035'!A:F,5,0) -> -5 | J34: =F34-VLOOKUP(A34,'26035'!A:F,6,0) -> 0
A35: 31 | B35: Core Module Parts Clock Stop | C35: Material Management | D35: 46143 | E35: 46143 | H35: =D35-VLOOKUP(A35,'26035'!A:F,4,0) -> 0 | I35: =E35-VLOOKUP(A35,'26035'!A:F,5,0) -> 0 | J35: =F35-VLOOKUP(A35,'26035'!A:F,6,0) -> 0
A36: 32GATE 2 | B36: Core Modules Kitted BFS2 | C36: Material Management | D36: 46143 | E36: 46134 | G36: BFS2 | H36: =D36-VLOOKUP(A36,'26035'!A:F,4,0) -> 0 | I36: =E36-VLOOKUP(A36,'26035'!A:F,5,0) -> -5 | J36: =F36-VLOOKUP(A36,'26035'!A:F,6,0) -> 0
A37: 32-MODULE 31 | B37: MODULE 31 Core Modules Kitted | C37: Material Management | D37: 46139 | E37: 46134 | H37: =D37-VLOOKUP(A37,'26035'!A:F,4,0) -> 0 | I37: =E37-VLOOKUP(A37,'26035'!A:F,5,0) -> -5 | J37: =F37-VLOOKUP(A37,'26035'!A:F,6,0) -> 0
A38: 32-MODULE 32 | B38: MODULE 32 Core Modules Kitted | C38: Material Management | D38: 46139 | E38: 46134 | H38: =D38-VLOOKUP(A38,'26035'!A:F,4,0) -> 0 | I38: =E38-VLOOKUP(A38,'26035'!A:F,5,0) -> -5 | J38: =F38-VLOOKUP(A38,'26035'!A:F,6,0) -> 0
A39: 32-MODULE 33 | B39: MODULE 33 Core Modules Kitted | C39: Material Management | D39: 46139 | E39: 46134 | H39: =D39-VLOOKUP(A39,'26035'!A:F,4,0) -> 0 | I39: =E39-VLOOKUP(A39,'26035'!A:F,5,0) -> -5 | J39: =F39-VLOOKUP(A39,'26035'!A:F,6,0) -> 0
A40: 32-MODULE 41 | B40: MODULE 41 Core Modules Kitted | C40: Material Management | D40: 46139 | E40: 46134 | H40: =D40-VLOOKUP(A40,'26035'!A:F,4,0) -> 0 | I40: =E40-VLOOKUP(A40,'26035'!A:F,5,0) -> -5 | J40: =F40-VLOOKUP(A40,'26035'!A:F,6,0) -> 0
...

Sheet 26035 (MST+5)
A1: Task_no | B1: Task_name | C1: task_owner | D1: finish_date | E1: project_complete_date | F1: actual_finish_date | G1: flag_func | H1: change_DF | I1: change_PCD | J1: change_ACD
A2: 1 | B2: TRC COST DIW | C2: Customer Services | D2: 46089 | E2: 46089 | H2: =D2-VLOOKUP(A2,'26035'!A:F,4,0) -> 0 | I2: =E2-VLOOKUP(A2,'26035'!A:F,5,0) -> 0 | J2: =F2-VLOOKUP(A2,'26035'!A:F,6,0) -> 0
A3: 3 | B3: Input Check COST DIW | C3: Module Change | D3: 46094 | E3: 46094 | H3: =D3-VLOOKUP(A3,'26035'!A:F,4,0) -> 0 | I3: =E3-VLOOKUP(A3,'26035'!A:F,5,0) -> 0 | J3: =F3-VLOOKUP(A3,'26035'!A:F,6,0) -> 0
A4: 4 | B4: Induction Induction COST DIW | C4: Planning and Business Support | D4: 46096 | E4: 46096 | F4: 46096 | G4: Induction | H4: =D4-VLOOKUP(A4,'26035'!A:F,4,0) -> 0 | I4: =E4-VLOOKUP(A4,'26035'!A:F,5,0) -> 0 | J4: =F4-VLOOKUP(A4,'26035'!A:F,6,0) -> 0
A5: 5 | B5: Engine Bulk Strip COST DIW | C5: Module Change | D5: 46103 | E5: 46103 | H5: =D5-VLOOKUP(A5,'26035'!A:F,4,0) -> 0 | I5: =E5-VLOOKUP(A5,'26035'!A:F,5,0) -> 0 | J5: =F5-VLOOKUP(A5,'26035'!A:F,6,0) -> 0
A6: 6GATE 1 | B6: Components Sentencing COST DIW | C6: Module Change | D6: 46107 | E6: 46107 | H6: =D6-VLOOKUP(A6,'26035'!A:F,4,0) -> 0 | I6: =E6-VLOOKUP(A6,'26035'!A:F,5,0) -> 0 | J6: =F6-VLOOKUP(A6,'26035'!A:F,6,0) -> 0
A7: 7 | B7: Components Receipt at Vendor COST DIW | C7: Logistics | D7: 46114 | E7: 46114 | H7: =D7-VLOOKUP(A7,'26035'!A:F,4,0) -> 0 | I7: =E7-VLOOKUP(A7,'26035'!A:F,5,0) -> 0 | J7: =F7-VLOOKUP(A7,'26035'!A:F,6,0) -> 0
A8: 8GATE 1 | B8: Engine Inspection COST DIW | C8: Module Change | D8: 46109 | E8: 46109 | H8: =D8-VLOOKUP(A8,'26035'!A:F,4,0) -> 0 | I8: =E8-VLOOKUP(A8,'26035'!A:F,5,0) -> 0 | J8: =F8-VLOOKUP(A8,'26035'!A:F,6,0) -> 0
A9: 9 | B9: Module Strip COST DIW | C9: Module Repair | D9: 46109 | E9: 46109 | H9: =D9-VLOOKUP(A9,'26035'!A:F,4,0) -> 0 | I9: =E9-VLOOKUP(A9,'26035'!A:F,5,0) -> 0 | J9: =F9-VLOOKUP(A9,'26035'!A:F,6,0) -> 0
A10: 9-MODULE 31 | B10: MODULE 31 Module Strip | C10: Module Repair | D10: 46109 | E10: 46109 | H10: =D10-VLOOKUP(A10,'26035'!A:F,4,0) -> 0 | I10: =E10-VLOOKUP(A10,'26035'!A:F,5,0) -> 0 | J10: =F10-VLOOKUP(A10,'26035'!A:F,6,0) -> 0
A11: 9-MODULE 32 | B11: MODULE 32 Module Strip | C11: Module Repair | D11: 46109 | E11: 46109 | H11: =D11-VLOOKUP(A11,'26035'!A:F,4,0) -> 0 | I11: =E11-VLOOKUP(A11,'26035'!A:F,5,0) -> 0 | J11: =F11-VLOOKUP(A11,'26035'!A:F,6,0) -> 0
A12: 9-MODULE 33 | B12: MODULE 33 Module Strip | C12: Module Repair | D12: 46109 | E12: 46109 | H12: =D12-VLOOKUP(A12,'26035'!A:F,4,0) -> 0 | I12: =E12-VLOOKUP(A12,'26035'!A:F,5,0) -> 0 | J12: =F12-VLOOKUP(A12,'26035'!A:F,6,0) -> 0
A13: 9-MODULE 41 | B13: MODULE 41 Module Strip | C13: Module Repair | D13: 46109 | E13: 46109 | H13: =D13-VLOOKUP(A13,'26035'!A:F,4,0) -> 0 | I13: =E13-VLOOKUP(A13,'26035'!A:F,5,0) -> 0 | J13: =F13-VLOOKUP(A13,'26035'!A:F,6,0) -> 0
A14: 9-MODULE 51 | B14: MODULE 51 Module Strip | C14: Module Repair | D14: 46109 | E14: 46109 | H14: =D14-VLOOKUP(A14,'26035'!A:F,4,0) -> 0 | I14: =E14-VLOOKUP(A14,'26035'!A:F,5,0) -> 0 | J14: =F14-VLOOKUP(A14,'26035'!A:F,6,0) -> 0
A15: 9-MODULE 52 | B15: MODULE 52 Module Strip | C15: Module Repair | D15: 46109 | E15: 46109 | H15: =D15-VLOOKUP(A15,'26035'!A:F,4,0) -> 0 | I15: =E15-VLOOKUP(A15,'26035'!A:F,5,0) -> 0 | J15: =F15-VLOOKUP(A15,'26035'!A:F,6,0) -> 0
A16: 10GATE 1 | B16: Critical Inspection | C16: Module Repair | D16: 46108 | E16: 46108 | H16: =D16-VLOOKUP(A16,'26035'!A:F,4,0) -> 0 | I16: =E16-VLOOKUP(A16,'26035'!A:F,5,0) -> 0 | J16: =F16-VLOOKUP(A16,'26035'!A:F,6,0) -> 0
A17: 13 | B17: Critical Parts Orders | C17: Material Management | D17: 46109 | E17: 46109 | H17: =D17-VLOOKUP(A17,'26035'!A:F,4,0) -> 0 | I17: =E17-VLOOKUP(A17,'26035'!A:F,5,0) -> 0 | J17: =F17-VLOOKUP(A17,'26035'!A:F,6,0) -> 0
A18: 14 | B18: Overseas Receipt At Vendor | C18: Logistics | D18: 46115 | E18: 46115 | H18: =D18-VLOOKUP(A18,'26035'!A:F,4,0) -> 0 | I18: =E18-VLOOKUP(A18,'26035'!A:F,5,0) -> 0 | J18: =F18-VLOOKUP(A18,'26035'!A:F,6,0) -> 0
A19: 15GATE 1 | B19: Inspection BLT COST DIW | C19: Bench | D19: 46108 | E19: 46108 | G19: BLT | H19: =D19-VLOOKUP(A19,'26035'!A:F,4,0) -> 0 | I19: =E19-VLOOKUP(A19,'26035'!A:F,5,0) -> 0 | J19: =F19-VLOOKUP(A19,'26035'!A:F,6,0) -> 0
A20: 15-MODULE 31 | B20: MODULE 31 Inspection | C20: Bench | D20: 46108 | E20: 46108 | H20: =D20-VLOOKUP(A20,'26035'!A:F,4,0) -> 0 | I20: =E20-VLOOKUP(A20,'26035'!A:F,5,0) -> 0 | J20: =F20-VLOOKUP(A20,'26035'!A:F,6,0) -> 0
A21: 15-MODULE 32 | B21: MODULE 32 Inspection | C21: Bench | D21: 46108 | E21: 46108 | H21: =D21-VLOOKUP(A21,'26035'!A:F,4,0) -> 0 | I21: =E21-VLOOKUP(A21,'26035'!A:F,5,0) -> 0 | J21: =F21-VLOOKUP(A21,'26035'!A:F,6,0) -> 0
A22: 15-MODULE 33 | B22: MODULE 33 Inspection | C22: Bench | D22: 46108 | E22: 46108 | H22: =D22-VLOOKUP(A22,'26035'!A:F,4,0) -> 0 | I22: =E22-VLOOKUP(A22,'26035'!A:F,5,0) -> 0 | J22: =F22-VLOOKUP(A22,'26035'!A:F,6,0) -> 0
A23: 15-MODULE 41 | B23: MODULE 41 Inspection | C23: Bench | D23: 46108 | E23: 46108 | H23: =D23-VLOOKUP(A23,'26035'!A:F,4,0) -> 0 | I23: =E23-VLOOKUP(A23,'26035'!A:F,5,0) -> 0 | J23: =F23-VLOOKUP(A23,'26035'!A:F,6,0) -> 0
A24: 15-MODULE 51 | B24: MODULE 51 Inspection | C24: Bench | D24: 46108 | E24: 46108 | H24: =D24-VLOOKUP(A24,'26035'!A:F,4,0) -> 0 | I24: =E24-VLOOKUP(A24,'26035'!A:F,5,0) -> 0 | J24: =F24-VLOOKUP(A24,'26035'!A:F,6,0) -> 0
A25: 15-MODULE 52 | B25: MODULE 52 Inspection | C25: Bench | D25: 46108 | E25: 46108 | H25: =D25-VLOOKUP(A25,'26035'!A:F,4,0) -> 0 | I25: =E25-VLOOKUP(A25,'26035'!A:F,5,0) -> 0 | J25: =F25-VLOOKUP(A25,'26035'!A:F,6,0) -> 0
A26: 17 | B26: Instruct external parts supply | C26: Customer Services | D26: 46104 | E26: 46104 | H26: =D26-VLOOKUP(A26,'26035'!A:F,4,0) -> 0 | I26: =E26-VLOOKUP(A26,'26035'!A:F,5,0) -> 0 | J26: =F26-VLOOKUP(A26,'26035'!A:F,6,0) -> 0
A27: 18 | B27: Inspection (XWB HPC) | C27: Bench | D27: 46113 | E27: 46113 | H27: =D27-VLOOKUP(A27,'26035'!A:F,4,0) -> 0 | I27: =E27-VLOOKUP(A27,'26035'!A:F,5,0) -> 0 | J27: =F27-VLOOKUP(A27,'26035'!A:F,6,0) -> 0
A28: 19 | B28: Parts orders | C28: Material Management | D28: 46114 | E28: 46114 | H28: =D28-VLOOKUP(A28,'26035'!A:F,4,0) -> 0 | I28: =E28-VLOOKUP(A28,'26035'!A:F,5,0) -> 0 | J28: =F28-VLOOKUP(A28,'26035'!A:F,6,0) -> 0
A29: 20 | B29: Rework Spare Clock Stop | C29: Material Management | D29: 46118 | E29: 46118 | H29: =D29-VLOOKUP(A29,'26035'!A:F,4,0) -> 0 | I29: =E29-VLOOKUP(A29,'26035'!A:F,5,0) -> 0 | J29: =F29-VLOOKUP(A29,'26035'!A:F,6,0) -> 0
A30: 23 | B30: Customer Material Approval | C30: Customer Services | D30: 46124 | E30: 46124 | H30: =D30-VLOOKUP(A30,'26035'!A:F,4,0) -> 0 | I30: =E30-VLOOKUP(A30,'26035'!A:F,5,0) -> 0 | J30: =F30-VLOOKUP(A30,'26035'!A:F,6,0) -> 0
A31: 27 | B31: Kitting Review | C31: Material Management | D31: 46137 | E31: 46137 | H31: =D31-VLOOKUP(A31,'26035'!A:F,4,0) -> 0 | I31: =E31-VLOOKUP(A31,'26035'!A:F,5,0) -> 0 | J31: =F31-VLOOKUP(A31,'26035'!A:F,6,0) -> 0
A32: 28 | B32: Component Repair BFS | C32: Material Management | D32: 46145 | E32: 46145 | F32: 46127 | G32: BFS | H32: =D32-VLOOKUP(A32,'26035'!A:F,4,0) -> 0 | I32: =E32-VLOOKUP(A32,'26035'!A:F,5,0) -> 0 | J32: =F32-VLOOKUP(A32,'26035'!A:F,6,0) -> 46127
A33: 29 | B33: Receive orders BFS | C33: Material Management | D33: 46145 | E33: 46145 | G33: BFS | H33: =D33-VLOOKUP(A33,'26035'!A:F,4,0) -> 0 | I33: =E33-VLOOKUP(A33,'26035'!A:F,5,0) -> 0 | J33: =F33-VLOOKUP(A33,'26035'!A:F,6,0) -> 0
A34: 30 | B34: Receive overseas repair - core engine parts BFS | C34: Material Management | D34: 46141 | E34: 46141 | G34: BFS | H34: =D34-VLOOKUP(A34,'26035'!A:F,4,0) -> 0 | I34: =E34-VLOOKUP(A34,'26035'!A:F,5,0) -> 0 | J34: =F34-VLOOKUP(A34,'26035'!A:F,6,0) -> 0
A35: 31 | B35: Core Module Parts Clock Stop | C35: Material Management | D35: 46143 | E35: 46143 | H35: =D35-VLOOKUP(A35,'26035'!A:F,4,0) -> 0 | I35: =E35-VLOOKUP(A35,'26035'!A:F,5,0) -> 0 | J35: =F35-VLOOKUP(A35,'26035'!A:F,6,0) -> 0
A36: 32GATE 2 | B36: Core Modules Kitted BFS2 | C36: Material Management | D36: 46143 | E36: 46139 | G36: BFS2 | H36: =D36-VLOOKUP(A36,'26035'!A:F,4,0) -> 0 | I36: =E36-VLOOKUP(A36,'26035'!A:F,5,0) -> 0 | J36: =F36-VLOOKUP(A36,'26035'!A:F,6,0) -> 0
A37: 32-MODULE 31 | B37: MODULE 31 Core Modules Kitted | C37: Material Management | D37: 46139 | E37: 46139 | H37: =D37-VLOOKUP(A37,'26035'!A:F,4,0) -> 0 | I37: =E37-VLOOKUP(A37,'26035'!A:F,5,0) -> 0 | J37: =F37-VLOOKUP(A37,'26035'!A:F,6,0) -> 0
A38: 32-MODULE 32 | B38: MODULE 32 Core Modules Kitted | C38: Material Management | D38: 46139 | E38: 46139 | H38: =D38-VLOOKUP(A38,'26035'!A:F,4,0) -> 0 | I38: =E38-VLOOKUP(A38,'26035'!A:F,5,0) -> 0 | J38: =F38-VLOOKUP(A38,'26035'!A:F,6,0) -> 0
A39: 32-MODULE 33 | B39: MODULE 33 Core Modules Kitted | C39: Material Management | D39: 46139 | E39: 46139 | H39: =D39-VLOOKUP(A39,'26035'!A:F,4,0) -> 0 | I39: =E39-VLOOKUP(A39,'26035'!A:F,5,0) -> 0 | J39: =F39-VLOOKUP(A39,'26035'!A:F,6,0) -> 0
A40: 32-MODULE 41 | B40: MODULE 41 Core Modules Kitted | C40: Material Management | D40: 46139 | E40: 46139 | H40: =D40-VLOOKUP(A40,'26035'!A:F,4,0) -> 0 | I40: =E40-VLOOKUP(A40,'26035'!A:F,5,0) -> 0 | J40: =F40-VLOOKUP(A40,'26035'!A:F,6,0) -> 0
...

Sheet 26035 (MST hit BLT)
A1: Task_no | B1: Task_name | C1: task_owner | D1: finish_date | E1: project_complete_date | F1: actual_finish_date | G1: flag_func | H1: change_DF | I1: change_PCD | J1: change_ACD
A2: 1 | B2: TRC COST DIW | C2: Customer Services | D2: 46089 | E2: 46089 | H2: =D2-VLOOKUP(A2,'26035'!A:F,4,0) -> 0 | I2: =E2-VLOOKUP(A2,'26035'!A:F,5,0) -> 0 | J2: =F2-VLOOKUP(A2,'26035'!A:F,6,0) -> 0
A3: 3 | B3: Input Check COST DIW | C3: Module Change | D3: 46094 | E3: 46094 | H3: =D3-VLOOKUP(A3,'26035'!A:F,4,0) -> 0 | I3: =E3-VLOOKUP(A3,'26035'!A:F,5,0) -> 0 | J3: =F3-VLOOKUP(A3,'26035'!A:F,6,0) -> 0
A4: 4 | B4: Induction Induction COST DIW | C4: Planning and Business Support | D4: 46096 | E4: 46096 | F4: 46096 | G4: Induction | H4: =D4-VLOOKUP(A4,'26035'!A:F,4,0) -> 0 | I4: =E4-VLOOKUP(A4,'26035'!A:F,5,0) -> 0 | J4: =F4-VLOOKUP(A4,'26035'!A:F,6,0) -> 0
A5: 5 | B5: Engine Bulk Strip COST DIW | C5: Module Change | D5: 46103 | E5: 46103 | H5: =D5-VLOOKUP(A5,'26035'!A:F,4,0) -> 0 | I5: =E5-VLOOKUP(A5,'26035'!A:F,5,0) -> 0 | J5: =F5-VLOOKUP(A5,'26035'!A:F,6,0) -> 0
A6: 6GATE 1 | B6: Components Sentencing COST DIW | C6: Module Change | D6: 46107 | E6: 46107 | H6: =D6-VLOOKUP(A6,'26035'!A:F,4,0) -> 0 | I6: =E6-VLOOKUP(A6,'26035'!A:F,5,0) -> 0 | J6: =F6-VLOOKUP(A6,'26035'!A:F,6,0) -> 0
A7: 7 | B7: Components Receipt at Vendor COST DIW | C7: Logistics | D7: 46114 | E7: 46114 | H7: =D7-VLOOKUP(A7,'26035'!A:F,4,0) -> 0 | I7: =E7-VLOOKUP(A7,'26035'!A:F,5,0) -> 0 | J7: =F7-VLOOKUP(A7,'26035'!A:F,6,0) -> 0
A8: 8GATE 1 | B8: Engine Inspection COST DIW | C8: Module Change | D8: 46109 | E8: 46109 | H8: =D8-VLOOKUP(A8,'26035'!A:F,4,0) -> 0 | I8: =E8-VLOOKUP(A8,'26035'!A:F,5,0) -> 0 | J8: =F8-VLOOKUP(A8,'26035'!A:F,6,0) -> 0
A9: 9 | B9: Module Strip COST DIW | C9: Module Repair | D9: 46109 | E9: 46109 | H9: =D9-VLOOKUP(A9,'26035'!A:F,4,0) -> 0 | I9: =E9-VLOOKUP(A9,'26035'!A:F,5,0) -> 0 | J9: =F9-VLOOKUP(A9,'26035'!A:F,6,0) -> 0
A10: 9-MODULE 31 | B10: MODULE 31 Module Strip | C10: Module Repair | D10: 46109 | E10: 46109 | H10: =D10-VLOOKUP(A10,'26035'!A:F,4,0) -> 0 | I10: =E10-VLOOKUP(A10,'26035'!A:F,5,0) -> 0 | J10: =F10-VLOOKUP(A10,'26035'!A:F,6,0) -> 0
A11: 9-MODULE 32 | B11: MODULE 32 Module Strip | C11: Module Repair | D11: 46109 | E11: 46109 | H11: =D11-VLOOKUP(A11,'26035'!A:F,4,0) -> 0 | I11: =E11-VLOOKUP(A11,'26035'!A:F,5,0) -> 0 | J11: =F11-VLOOKUP(A11,'26035'!A:F,6,0) -> 0
A12: 9-MODULE 33 | B12: MODULE 33 Module Strip | C12: Module Repair | D12: 46109 | E12: 46109 | H12: =D12-VLOOKUP(A12,'26035'!A:F,4,0) -> 0 | I12: =E12-VLOOKUP(A12,'26035'!A:F,5,0) -> 0 | J12: =F12-VLOOKUP(A12,'26035'!A:F,6,0) -> 0
A13: 9-MODULE 41 | B13: MODULE 41 Module Strip | C13: Module Repair | D13: 46109 | E13: 46109 | H13: =D13-VLOOKUP(A13,'26035'!A:F,4,0) -> 0 | I13: =E13-VLOOKUP(A13,'26035'!A:F,5,0) -> 0 | J13: =F13-VLOOKUP(A13,'26035'!A:F,6,0) -> 0
A14: 9-MODULE 51 | B14: MODULE 51 Module Strip | C14: Module Repair | D14: 46109 | E14: 46109 | H14: =D14-VLOOKUP(A14,'26035'!A:F,4,0) -> 0 | I14: =E14-VLOOKUP(A14,'26035'!A:F,5,0) -> 0 | J14: =F14-VLOOKUP(A14,'26035'!A:F,6,0) -> 0
A15: 9-MODULE 52 | B15: MODULE 52 Module Strip | C15: Module Repair | D15: 46109 | E15: 46109 | H15: =D15-VLOOKUP(A15,'26035'!A:F,4,0) -> 0 | I15: =E15-VLOOKUP(A15,'26035'!A:F,5,0) -> 0 | J15: =F15-VLOOKUP(A15,'26035'!A:F,6,0) -> 0
A16: 10GATE 1 | B16: Critical Inspection | C16: Module Repair | D16: 46108 | E16: 46108 | H16: =D16-VLOOKUP(A16,'26035'!A:F,4,0) -> 0 | I16: =E16-VLOOKUP(A16,'26035'!A:F,5,0) -> 0 | J16: =F16-VLOOKUP(A16,'26035'!A:F,6,0) -> 0
A17: 13 | B17: Critical Parts Orders | C17: Material Management | D17: 46109 | E17: 46109 | H17: =D17-VLOOKUP(A17,'26035'!A:F,4,0) -> 0 | I17: =E17-VLOOKUP(A17,'26035'!A:F,5,0) -> 0 | J17: =F17-VLOOKUP(A17,'26035'!A:F,6,0) -> 0
A18: 14 | B18: Overseas Receipt At Vendor | C18: Logistics | D18: 46115 | E18: 46115 | H18: =D18-VLOOKUP(A18,'26035'!A:F,4,0) -> 0 | I18: =E18-VLOOKUP(A18,'26035'!A:F,5,0) -> 0 | J18: =F18-VLOOKUP(A18,'26035'!A:F,6,0) -> 0
A19: 15GATE 1 | B19: Inspection BLT COST DIW | C19: Bench | D19: 46108 | E19: 46108 | G19: BLT | H19: =D19-VLOOKUP(A19,'26035'!A:F,4,0) -> 0 | I19: =E19-VLOOKUP(A19,'26035'!A:F,5,0) -> 0 | J19: =F19-VLOOKUP(A19,'26035'!A:F,6,0) -> 0
A20: 15-MODULE 31 | B20: MODULE 31 Inspection | C20: Bench | D20: 46108 | E20: 46108 | H20: =D20-VLOOKUP(A20,'26035'!A:F,4,0) -> 0 | I20: =E20-VLOOKUP(A20,'26035'!A:F,5,0) -> 0 | J20: =F20-VLOOKUP(A20,'26035'!A:F,6,0) -> 0
A21: 15-MODULE 32 | B21: MODULE 32 Inspection | C21: Bench | D21: 46108 | E21: 46108 | H21: =D21-VLOOKUP(A21,'26035'!A:F,4,0) -> 0 | I21: =E21-VLOOKUP(A21,'26035'!A:F,5,0) -> 0 | J21: =F21-VLOOKUP(A21,'26035'!A:F,6,0) -> 0
A22: 15-MODULE 33 | B22: MODULE 33 Inspection | C22: Bench | D22: 46108 | E22: 46108 | H22: =D22-VLOOKUP(A22,'26035'!A:F,4,0) -> 0 | I22: =E22-VLOOKUP(A22,'26035'!A:F,5,0) -> 0 | J22: =F22-VLOOKUP(A22,'26035'!A:F,6,0) -> 0
A23: 15-MODULE 41 | B23: MODULE 41 Inspection | C23: Bench | D23: 46108 | E23: 46108 | H23: =D23-VLOOKUP(A23,'26035'!A:F,4,0) -> 0 | I23: =E23-VLOOKUP(A23,'26035'!A:F,5,0) -> 0 | J23: =F23-VLOOKUP(A23,'26035'!A:F,6,0) -> 0
A24: 15-MODULE 51 | B24: MODULE 51 Inspection | C24: Bench | D24: 46108 | E24: 46108 | H24: =D24-VLOOKUP(A24,'26035'!A:F,4,0) -> 0 | I24: =E24-VLOOKUP(A24,'26035'!A:F,5,0) -> 0 | J24: =F24-VLOOKUP(A24,'26035'!A:F,6,0) -> 0
A25: 15-MODULE 52 | B25: MODULE 52 Inspection | C25: Bench | D25: 46108 | E25: 46108 | H25: =D25-VLOOKUP(A25,'26035'!A:F,4,0) -> 0 | I25: =E25-VLOOKUP(A25,'26035'!A:F,5,0) -> 0 | J25: =F25-VLOOKUP(A25,'26035'!A:F,6,0) -> 0
A26: 17 | B26: Instruct external parts supply | C26: Customer Services | D26: 46104 | E26: 46104 | H26: =D26-VLOOKUP(A26,'26035'!A:F,4,0) -> 0 | I26: =E26-VLOOKUP(A26,'26035'!A:F,5,0) -> 0 | J26: =F26-VLOOKUP(A26,'26035'!A:F,6,0) -> 0
A27: 18 | B27: Inspection (XWB HPC) | C27: Bench | D27: 46113 | E27: 46113 | H27: =D27-VLOOKUP(A27,'26035'!A:F,4,0) -> 0 | I27: =E27-VLOOKUP(A27,'26035'!A:F,5,0) -> 0 | J27: =F27-VLOOKUP(A27,'26035'!A:F,6,0) -> 0
A28: 19 | B28: Parts orders | C28: Material Management | D28: 46114 | E28: 46114 | H28: =D28-VLOOKUP(A28,'26035'!A:F,4,0) -> 0 | I28: =E28-VLOOKUP(A28,'26035'!A:F,5,0) -> 0 | J28: =F28-VLOOKUP(A28,'26035'!A:F,6,0) -> 0
A29: 20 | B29: Rework Spare Clock Stop | C29: Material Management | D29: 46118 | E29: 46118 | H29: =D29-VLOOKUP(A29,'26035'!A:F,4,0) -> 0 | I29: =E29-VLOOKUP(A29,'26035'!A:F,5,0) -> 0 | J29: =F29-VLOOKUP(A29,'26035'!A:F,6,0) -> 0
A30: 23 | B30: Customer Material Approval | C30: Customer Services | D30: 46124 | E30: 46124 | H30: =D30-VLOOKUP(A30,'26035'!A:F,4,0) -> 0 | I30: =E30-VLOOKUP(A30,'26035'!A:F,5,0) -> 0 | J30: =F30-VLOOKUP(A30,'26035'!A:F,6,0) -> 0
A31: 27 | B31: Kitting Review | C31: Material Management | D31: 46137 | E31: 46137 | H31: =D31-VLOOKUP(A31,'26035'!A:F,4,0) -> 0 | I31: =E31-VLOOKUP(A31,'26035'!A:F,5,0) -> 0 | J31: =F31-VLOOKUP(A31,'26035'!A:F,6,0) -> 0
A32: 28 | B32: Component Repair BFS | C32: Material Management | D32: 46145 | E32: 46145 | F32: 46127 | G32: BFS | H32: =D32-VLOOKUP(A32,'26035'!A:F,4,0) -> 0 | I32: =E32-VLOOKUP(A32,'26035'!A:F,5,0) -> 0 | J32: =F32-VLOOKUP(A32,'26035'!A:F,6,0) -> 46127
A33: 29 | B33: Receive orders BFS | C33: Material Management | D33: 46145 | E33: 46108 | G33: BFS | H33: =D33-VLOOKUP(A33,'26035'!A:F,4,0) -> 0 | I33: =E33-VLOOKUP(A33,'26035'!A:F,5,0) -> -37 | J33: =F33-VLOOKUP(A33,'26035'!A:F,6,0) -> 0
A34: 30 | B34: Receive overseas repair - core engine parts BFS | C34: Material Management | D34: 46141 | E34: 46108 | G34: BFS | H34: =D34-VLOOKUP(A34,'26035'!A:F,4,0) -> 0 | I34: =E34-VLOOKUP(A34,'26035'!A:F,5,0) -> -33 | J34: =F34-VLOOKUP(A34,'26035'!A:F,6,0) -> 0
A35: 31 | B35: Core Module Parts Clock Stop | C35: Material Management | D35: 46143 | E35: 46143 | H35: =D35-VLOOKUP(A35,'26035'!A:F,4,0) -> 0 | I35: =E35-VLOOKUP(A35,'26035'!A:F,5,0) -> 0 | J35: =F35-VLOOKUP(A35,'26035'!A:F,6,0) -> 0
A36: 32GATE 2 | B36: Core Modules Kitted BFS2 | C36: Material Management | D36: 46143 | E36: 46108 | G36: BFS2 | H36: =D36-VLOOKUP(A36,'26035'!A:F,4,0) -> 0 | I36: =E36-VLOOKUP(A36,'26035'!A:F,5,0) -> -31 | J36: =F36-VLOOKUP(A36,'26035'!A:F,6,0) -> 0
A37: 32-MODULE 31 | B37: MODULE 31 Core Modules Kitted | C37: Material Management | D37: 46139 | E37: 46108 | H37: =D37-VLOOKUP(A37,'26035'!A:F,4,0) -> 0 | I37: =E37-VLOOKUP(A37,'26035'!A:F,5,0) -> -31 | J37: =F37-VLOOKUP(A37,'26035'!A:F,6,0) -> 0
A38: 32-MODULE 32 | B38: MODULE 32 Core Modules Kitted | C38: Material Management | D38: 46139 | E38: 46108 | H38: =D38-VLOOKUP(A38,'26035'!A:F,4,0) -> 0 | I38: =E38-VLOOKUP(A38,'26035'!A:F,5,0) -> -31 | J38: =F38-VLOOKUP(A38,'26035'!A:F,6,0) -> 0
A39: 32-MODULE 33 | B39: MODULE 33 Core Modules Kitted | C39: Material Management | D39: 46139 | E39: 46108 | H39: =D39-VLOOKUP(A39,'26035'!A:F,4,0) -> 0 | I39: =E39-VLOOKUP(A39,'26035'!A:F,5,0) -> -31 | J39: =F39-VLOOKUP(A39,'26035'!A:F,6,0) -> 0
A40: 32-MODULE 41 | B40: MODULE 41 Core Modules Kitted | C40: Material Management | D40: 46139 | E40: 46108 | H40: =D40-VLOOKUP(A40,'26035'!A:F,4,0) -> 0 | I40: =E40-VLOOKUP(A40,'26035'!A:F,5,0) -> -31 | J40: =F40-VLOOKUP(A40,'26035'!A:F,6,0) -> 0
...

Sheet 26035 (MST back to original)
A1: Task_no | B1: Task_name | C1: task_owner | D1: finish_date | E1: project_complete_date | F1: actual_finish_date | G1: flag_func | H1: change_DF | I1: change_PCD | J1: change_ACD
A2: 1 | B2: TRC COST DIW | C2: Customer Services | D2: 46089 | E2: 46089 | H2: =D2-VLOOKUP(A2,'26035'!A:F,4,0) -> 0 | I2: =E2-VLOOKUP(A2,'26035'!A:F,5,0) -> 0 | J2: =F2-VLOOKUP(A2,'26035'!A:F,6,0) -> 0
A3: 3 | B3: Input Check COST DIW | C3: Module Change | D3: 46094 | E3: 46094 | H3: =D3-VLOOKUP(A3,'26035'!A:F,4,0) -> 0 | I3: =E3-VLOOKUP(A3,'26035'!A:F,5,0) -> 0 | J3: =F3-VLOOKUP(A3,'26035'!A:F,6,0) -> 0
A4: 4 | B4: Induction Induction COST DIW | C4: Planning and Business Support | D4: 46096 | E4: 46096 | F4: 46096 | G4: Induction | H4: =D4-VLOOKUP(A4,'26035'!A:F,4,0) -> 0 | I4: =E4-VLOOKUP(A4,'26035'!A:F,5,0) -> 0 | J4: =F4-VLOOKUP(A4,'26035'!A:F,6,0) -> 0
A5: 5 | B5: Engine Bulk Strip COST DIW | C5: Module Change | D5: 46103 | E5: 46103 | H5: =D5-VLOOKUP(A5,'26035'!A:F,4,0) -> 0 | I5: =E5-VLOOKUP(A5,'26035'!A:F,5,0) -> 0 | J5: =F5-VLOOKUP(A5,'26035'!A:F,6,0) -> 0
A6: 6GATE 1 | B6: Components Sentencing COST DIW | C6: Module Change | D6: 46107 | E6: 46107 | H6: =D6-VLOOKUP(A6,'26035'!A:F,4,0) -> 0 | I6: =E6-VLOOKUP(A6,'26035'!A:F,5,0) -> 0 | J6: =F6-VLOOKUP(A6,'26035'!A:F,6,0) -> 0
A7: 7 | B7: Components Receipt at Vendor COST DIW | C7: Logistics | D7: 46114 | E7: 46114 | H7: =D7-VLOOKUP(A7,'26035'!A:F,4,0) -> 0 | I7: =E7-VLOOKUP(A7,'26035'!A:F,5,0) -> 0 | J7: =F7-VLOOKUP(A7,'26035'!A:F,6,0) -> 0
A8: 8GATE 1 | B8: Engine Inspection COST DIW | C8: Module Change | D8: 46109 | E8: 46109 | H8: =D8-VLOOKUP(A8,'26035'!A:F,4,0) -> 0 | I8: =E8-VLOOKUP(A8,'26035'!A:F,5,0) -> 0 | J8: =F8-VLOOKUP(A8,'26035'!A:F,6,0) -> 0
A9: 9 | B9: Module Strip COST DIW | C9: Module Repair | D9: 46109 | E9: 46109 | H9: =D9-VLOOKUP(A9,'26035'!A:F,4,0) -> 0 | I9: =E9-VLOOKUP(A9,'26035'!A:F,5,0) -> 0 | J9: =F9-VLOOKUP(A9,'26035'!A:F,6,0) -> 0
A10: 9-MODULE 31 | B10: MODULE 31 Module Strip | C10: Module Repair | D10: 46109 | E10: 46109 | H10: =D10-VLOOKUP(A10,'26035'!A:F,4,0) -> 0 | I10: =E10-VLOOKUP(A10,'26035'!A:F,5,0) -> 0 | J10: =F10-VLOOKUP(A10,'26035'!A:F,6,0) -> 0
A11: 9-MODULE 32 | B11: MODULE 32 Module Strip | C11: Module Repair | D11: 46109 | E11: 46109 | H11: =D11-VLOOKUP(A11,'26035'!A:F,4,0) -> 0 | I11: =E11-VLOOKUP(A11,'26035'!A:F,5,0) -> 0 | J11: =F11-VLOOKUP(A11,'26035'!A:F,6,0) -> 0
A12: 9-MODULE 33 | B12: MODULE 33 Module Strip | C12: Module Repair | D12: 46109 | E12: 46109 | H12: =D12-VLOOKUP(A12,'26035'!A:F,4,0) -> 0 | I12: =E12-VLOOKUP(A12,'26035'!A:F,5,0) -> 0 | J12: =F12-VLOOKUP(A12,'26035'!A:F,6,0) -> 0
A13: 9-MODULE 41 | B13: MODULE 41 Module Strip | C13: Module Repair | D13: 46109 | E13: 46109 | H13: =D13-VLOOKUP(A13,'26035'!A:F,4,0) -> 0 | I13: =E13-VLOOKUP(A13,'26035'!A:F,5,0) -> 0 | J13: =F13-VLOOKUP(A13,'26035'!A:F,6,0) -> 0
A14: 9-MODULE 51 | B14: MODULE 51 Module Strip | C14: Module Repair | D14: 46109 | E14: 46109 | H14: =D14-VLOOKUP(A14,'26035'!A:F,4,0) -> 0 | I14: =E14-VLOOKUP(A14,'26035'!A:F,5,0) -> 0 | J14: =F14-VLOOKUP(A14,'26035'!A:F,6,0) -> 0
A15: 9-MODULE 52 | B15: MODULE 52 Module Strip | C15: Module Repair | D15: 46109 | E15: 46109 | H15: =D15-VLOOKUP(A15,'26035'!A:F,4,0) -> 0 | I15: =E15-VLOOKUP(A15,'26035'!A:F,5,0) -> 0 | J15: =F15-VLOOKUP(A15,'26035'!A:F,6,0) -> 0
A16: 10GATE 1 | B16: Critical Inspection | C16: Module Repair | D16: 46108 | E16: 46108 | H16: =D16-VLOOKUP(A16,'26035'!A:F,4,0) -> 0 | I16: =E16-VLOOKUP(A16,'26035'!A:F,5,0) -> 0 | J16: =F16-VLOOKUP(A16,'26035'!A:F,6,0) -> 0
A17: 13 | B17: Critical Parts Orders | C17: Material Management | D17: 46109 | E17: 46109 | H17: =D17-VLOOKUP(A17,'26035'!A:F,4,0) -> 0 | I17: =E17-VLOOKUP(A17,'26035'!A:F,5,0) -> 0 | J17: =F17-VLOOKUP(A17,'26035'!A:F,6,0) -> 0
A18: 14 | B18: Overseas Receipt At Vendor | C18: Logistics | D18: 46115 | E18: 46115 | H18: =D18-VLOOKUP(A18,'26035'!A:F,4,0) -> 0 | I18: =E18-VLOOKUP(A18,'26035'!A:F,5,0) -> 0 | J18: =F18-VLOOKUP(A18,'26035'!A:F,6,0) -> 0
A19: 15GATE 1 | B19: Inspection BLT COST DIW | C19: Bench | D19: 46108 | E19: 46108 | G19: BLT | H19: =D19-VLOOKUP(A19,'26035'!A:F,4,0) -> 0 | I19: =E19-VLOOKUP(A19,'26035'!A:F,5,0) -> 0 | J19: =F19-VLOOKUP(A19,'26035'!A:F,6,0) -> 0
A20: 15-MODULE 31 | B20: MODULE 31 Inspection | C20: Bench | D20: 46108 | E20: 46108 | H20: =D20-VLOOKUP(A20,'26035'!A:F,4,0) -> 0 | I20: =E20-VLOOKUP(A20,'26035'!A:F,5,0) -> 0 | J20: =F20-VLOOKUP(A20,'26035'!A:F,6,0) -> 0
A21: 15-MODULE 32 | B21: MODULE 32 Inspection | C21: Bench | D21: 46108 | E21: 46108 | H21: =D21-VLOOKUP(A21,'26035'!A:F,4,0) -> 0 | I21: =E21-VLOOKUP(A21,'26035'!A:F,5,0) -> 0 | J21: =F21-VLOOKUP(A21,'26035'!A:F,6,0) -> 0
A22: 15-MODULE 33 | B22: MODULE 33 Inspection | C22: Bench | D22: 46108 | E22: 46108 | H22: =D22-VLOOKUP(A22,'26035'!A:F,4,0) -> 0 | I22: =E22-VLOOKUP(A22,'26035'!A:F,5,0) -> 0 | J22: =F22-VLOOKUP(A22,'26035'!A:F,6,0) -> 0
A23: 15-MODULE 41 | B23: MODULE 41 Inspection | C23: Bench | D23: 46108 | E23: 46108 | H23: =D23-VLOOKUP(A23,'26035'!A:F,4,0) -> 0 | I23: =E23-VLOOKUP(A23,'26035'!A:F,5,0) -> 0 | J23: =F23-VLOOKUP(A23,'26035'!A:F,6,0) -> 0
A24: 15-MODULE 51 | B24: MODULE 51 Inspection | C24: Bench | D24: 46108 | E24: 46108 | H24: =D24-VLOOKUP(A24,'26035'!A:F,4,0) -> 0 | I24: =E24-VLOOKUP(A24,'26035'!A:F,5,0) -> 0 | J24: =F24-VLOOKUP(A24,'26035'!A:F,6,0) -> 0
A25: 15-MODULE 52 | B25: MODULE 52 Inspection | C25: Bench | D25: 46108 | E25: 46108 | H25: =D25-VLOOKUP(A25,'26035'!A:F,4,0) -> 0 | I25: =E25-VLOOKUP(A25,'26035'!A:F,5,0) -> 0 | J25: =F25-VLOOKUP(A25,'26035'!A:F,6,0) -> 0
A26: 17 | B26: Instruct external parts supply | C26: Customer Services | D26: 46104 | E26: 46104 | H26: =D26-VLOOKUP(A26,'26035'!A:F,4,0) -> 0 | I26: =E26-VLOOKUP(A26,'26035'!A:F,5,0) -> 0 | J26: =F26-VLOOKUP(A26,'26035'!A:F,6,0) -> 0
A27: 18 | B27: Inspection (XWB HPC) | C27: Bench | D27: 46113 | E27: 46113 | H27: =D27-VLOOKUP(A27,'26035'!A:F,4,0) -> 0 | I27: =E27-VLOOKUP(A27,'26035'!A:F,5,0) -> 0 | J27: =F27-VLOOKUP(A27,'26035'!A:F,6,0) -> 0
A28: 19 | B28: Parts orders | C28: Material Management | D28: 46114 | E28: 46114 | H28: =D28-VLOOKUP(A28,'26035'!A:F,4,0) -> 0 | I28: =E28-VLOOKUP(A28,'26035'!A:F,5,0) -> 0 | J28: =F28-VLOOKUP(A28,'26035'!A:F,6,0) -> 0
A29: 20 | B29: Rework Spare Clock Stop | C29: Material Management | D29: 46118 | E29: 46118 | H29: =D29-VLOOKUP(A29,'26035'!A:F,4,0) -> 0 | I29: =E29-VLOOKUP(A29,'26035'!A:F,5,0) -> 0 | J29: =F29-VLOOKUP(A29,'26035'!A:F,6,0) -> 0
A30: 23 | B30: Customer Material Approval | C30: Customer Services | D30: 46124 | E30: 46124 | H30: =D30-VLOOKUP(A30,'26035'!A:F,4,0) -> 0 | I30: =E30-VLOOKUP(A30,'26035'!A:F,5,0) -> 0 | J30: =F30-VLOOKUP(A30,'26035'!A:F,6,0) -> 0
A31: 27 | B31: Kitting Review | C31: Material Management | D31: 46137 | E31: 46137 | H31: =D31-VLOOKUP(A31,'26035'!A:F,4,0) -> 0 | I31: =E31-VLOOKUP(A31,'26035'!A:F,5,0) -> 0 | J31: =F31-VLOOKUP(A31,'26035'!A:F,6,0) -> 0
A32: 28 | B32: Component Repair BFS | C32: Material Management | D32: 46145 | E32: 46145 | F32: 46127 | G32: BFS | H32: =D32-VLOOKUP(A32,'26035'!A:F,4,0) -> 0 | I32: =E32-VLOOKUP(A32,'26035'!A:F,5,0) -> 0 | J32: =F32-VLOOKUP(A32,'26035'!A:F,6,0) -> 46127
A33: 29 | B33: Receive orders BFS | C33: Material Management | D33: 46145 | E33: 46145 | G33: BFS | H33: =D33-VLOOKUP(A33,'26035'!A:F,4,0) -> 0 | I33: =E33-VLOOKUP(A33,'26035'!A:F,5,0) -> 0 | J33: =F33-VLOOKUP(A33,'26035'!A:F,6,0) -> 0
A34: 30 | B34: Receive overseas repair - core engine parts BFS | C34: Material Management | D34: 46141 | E34: 46141 | G34: BFS | H34: =D34-VLOOKUP(A34,'26035'!A:F,4,0) -> 0 | I34: =E34-VLOOKUP(A34,'26035'!A:F,5,0) -> 0 | J34: =F34-VLOOKUP(A34,'26035'!A:F,6,0) -> 0
A35: 31 | B35: Core Module Parts Clock Stop | C35: Material Management | D35: 46143 | E35: 46143 | H35: =D35-VLOOKUP(A35,'26035'!A:F,4,0) -> 0 | I35: =E35-VLOOKUP(A35,'26035'!A:F,5,0) -> 0 | J35: =F35-VLOOKUP(A35,'26035'!A:F,6,0) -> 0
A36: 32GATE 2 | B36: Core Modules Kitted BFS2 | C36: Material Management | D36: 46143 | E36: 46139 | G36: BFS2 | H36: =D36-VLOOKUP(A36,'26035'!A:F,4,0) -> 0 | I36: =E36-VLOOKUP(A36,'26035'!A:F,5,0) -> 0 | J36: =F36-VLOOKUP(A36,'26035'!A:F,6,0) -> 0
A37: 32-MODULE 31 | B37: MODULE 31 Core Modules Kitted | C37: Material Management | D37: 46139 | E37: 46139 | H37: =D37-VLOOKUP(A37,'26035'!A:F,4,0) -> 0 | I37: =E37-VLOOKUP(A37,'26035'!A:F,5,0) -> 0 | J37: =F37-VLOOKUP(A37,'26035'!A:F,6,0) -> 0
A38: 32-MODULE 32 | B38: MODULE 32 Core Modules Kitted | C38: Material Management | D38: 46139 | E38: 46139 | H38: =D38-VLOOKUP(A38,'26035'!A:F,4,0) -> 0 | I38: =E38-VLOOKUP(A38,'26035'!A:F,5,0) -> 0 | J38: =F38-VLOOKUP(A38,'26035'!A:F,6,0) -> 0
A39: 32-MODULE 33 | B39: MODULE 33 Core Modules Kitted | C39: Material Management | D39: 46139 | E39: 46139 | H39: =D39-VLOOKUP(A39,'26035'!A:F,4,0) -> 0 | I39: =E39-VLOOKUP(A39,'26035'!A:F,5,0) -> 0 | J39: =F39-VLOOKUP(A39,'26035'!A:F,6,0) -> 0
A40: 32-MODULE 41 | B40: MODULE 41 Core Modules Kitted | C40: Material Management | D40: 46139 | E40: 46139 | H40: =D40-VLOOKUP(A40,'26035'!A:F,4,0) -> 0 | I40: =E40-VLOOKUP(A40,'26035'!A:F,5,0) -> 0 | J40: =F40-VLOOKUP(A40,'26035'!A:F,6,0) -> 0
...
